Workbook

Sheet кузов S (ВТ)
C2: Расходы на цели S без отсева | G2: Метрики S
B3: Неделя | C3: sub dxgy | D3: sub dxgy / gmv опции | E3: sub dxgy / gmv total | F3: NI / GMV опции | G3: SR | H3: SR 3 ступени | I3: CDR | J3: Com_del | K3: WoW | L3: Доставки водителей | M3: WoW | N3: Водители | O3: SH active | P3: Utilization | Q3: AVG Fare | R3: GMV | S3: GMV total
B4: 45803 | C4: 0 | D4: =IFERROR(C4/R4,0) -> 0 | E4: =IFERROR(C4/S4,0) -> 0 | F4: =VLOOKUP($B4,s!$A:$H,2,0) -> 0.17 | G4: =G18 -> 0.56603774 | H4: =G17 -> 0.22641509 | I4: =VLOOKUP($B4,s!$A:$H,3,0) -> 0.85 | J4: =VLOOKUP($B4,s!$A:$H,4,0) -> 782 | K4: =IFERROR(J4/J3-1,"-") -> - | L4: =L43 -> 726 | M4: =IFERROR(L4/L3-1,"-") -> - | N4: =K43 -> 53 | O4: =VLOOKUP($B4,s!$A:$H,5,0) -> 481 | P4: =VLOOKUP($B4,s!$A:$H,6,0) -> 0.41 | Q4: =VLOOKUP($B4,s!$A:$H,7,0) -> 821 | R4: =VLOOKUP($B4,s!$A:$H,8,0) -> 642405 | S4: =VLOOKUP(B4,total!A:B,2,0) -> 2023413
B5: 45825 | C5: =H24 -> 85100 | D5: =IFERROR(C5/R5,0) -> 0.13466745 | E5: =IFERROR(C5/S5,0) -> 0.044611076 | F5: =VLOOKUP($B5,s!$A:$H,2,0) -> 0.07 | G5: =G24 -> 0.44615385 | H5: =G23 -> 0.15384615 | I5: =VLOOKUP($B5,s!$A:$H,3,0) -> 0.91 | J5: =VLOOKUP($B5,s!$A:$H,4,0) -> 731 | K5: =IFERROR(J5/J4-1,"-") -> -0.065217391 | L5: =O41 -> 710 | M5: =IFERROR(L5/L4-1,"-") -> -0.022038567 | N5: =N41 -> 65 | O5: =VLOOKUP($B5,s!$A:$H,5,0) -> 560 | P5: =VLOOKUP($B5,s!$A:$H,6,0) -> 0.39 | Q5: =VLOOKUP($B5,s!$A:$H,7,0) -> 864 | R5: =VLOOKUP($B5,s!$A:$H,8,0) -> 631927 | S5: =VLOOKUP(B5,total!A:B,2,0) -> 1907598
B6: 45832 | C6: =H30 -> 107600 | D6: =IFERROR(C6/R6,0) -> 0.17132612 | E6: =IFERROR(C6/S6,0) -> 0.05724537 | F6: =VLOOKUP($B6,s!$A:$H,2,0) -> 0.02 | G6: =G30 -> 0.52307692 | H6: =G29 -> 0.23076923 | I6: =VLOOKUP($B6,s!$A:$H,3,0) -> 0.9 | J6: =VLOOKUP($B6,s!$A:$H,4,0) -> 830 | K6: =IFERROR(J6/J5-1,"-") -> 0.13543092 | L6: =R43 -> 778 | M6: =IFERROR(L6/L5-1,"-") -> 0.095774648 | N6: =Q43 -> 65 | O6: =VLOOKUP($B6,s!$A:$H,5,0) -> 551 | P6: =VLOOKUP($B6,s!$A:$H,6,0) -> 0.4 | Q6: =VLOOKUP($B6,s!$A:$H,7,0) -> 757 | R6: =VLOOKUP($B6,s!$A:$H,8,0) -> 628042 | S6: =VLOOKUP(B6,total!A:B,2,0) -> 1879628
B7: 45839 | C7: =H36 -> 101800 | D7: =IFERROR(C7/R7,0) -> 0.14663116 | E7: =IFERROR(C7/S7,0) -> 0.049804232 | F7: =VLOOKUP($B7,s!$A:$H,2,0) -> 0.02 | G7: =G36 -> 0.57627119 | H7: =G35 -> 0.20338983 | I7: =VLOOKUP($B7,s!$A:$H,3,0) -> 0.92 | J7: =VLOOKUP($B7,s!$A:$H,4,0) -> 875 | K7: =IFERROR(J7/J6-1,"-") -> 0.054216867 | L7: =U43 -> 847 | M7: =IFERROR(L7/L6-1,"-") -> 0.088688946 | N7: =T43 -> 59 | O7: =VLOOKUP($B7,s!$A:$H,5,0) -> 565 | P7: =VLOOKUP($B7,s!$A:$H,6,0) -> 0.41 | Q7: =VLOOKUP($B7,s!$A:$H,7,0) -> 793 | R7: =VLOOKUP($B7,s!$A:$H,8,0) -> 694259 | S7: =VLOOKUP(B7,total!A:B,2,0) -> 2044003
B8: 45846 | C8: =H42 -> 113200 | D8: =IFERROR(C8/R8,0) -> 0.14095135 | E8: =IFERROR(C8/S8,0) -> 0.05247205 | F8: =VLOOKUP($B8,s!$A:$H,2,0) -> 0.05 | G8: =G42 -> 0.62962963 | H8: =G41 -> 0.31481481 | I8: =VLOOKUP($B8,s!$A:$H,3,0) -> 0.86 | J8: =VLOOKUP($B8,s!$A:$H,4,0) -> 912 | K8: =IFERROR(J8/J7-1,"-") -> 0.042285714 | L8: =X43 -> 856 | M8: =IFERROR(L8/L7-1,"-") -> 0.010625738 | N8: =W43 -> 54 | O8: =VLOOKUP($B8,s!$A:$H,5,0) -> 610 | P8: =VLOOKUP($B8,s!$A:$H,6,0) -> 0.61 | Q8: =VLOOKUP($B8,s!$A:$H,7,0) -> 881 | R8: =VLOOKUP($B8,s!$A:$H,8,0) -> 803114 | S8: =VLOOKUP(B8,total!A:B,2,0) -> 2157339
B9: 45853 | C9: =H48 -> 101900 | D9: =IFERROR(C9/R9,0) -> 0.1442695 | E9: =IFERROR(C9/S9,0) -> 0.048160928 | F9: =VLOOKUP($B9,s!$A:$H,2,0) -> 0.04 | G9: =G48 -> 0.52727273 | H9: =G47 -> 0.29090909 | I9: =VLOOKUP($B9,s!$A:$H,3,0) -> 0.87 | J9: =VLOOKUP($B9,s!$A:$H,4,0) -> 771 | K9: =IFERROR(J9/J8-1,"-") -> -0.15460526 | L9: =AA43 -> 719 | M9: =IFERROR(L9/L8-1,"-") -> -0.16004673 | N9: =Z43 -> 55 | O9: =VLOOKUP($B9,s!$A:$H,5,0) -> 535 | P9: =VLOOKUP($B9,s!$A:$H,6,0) -> 0.49 | Q9: =VLOOKUP($B9,s!$A:$H,7,0) -> 916 | R9: =VLOOKUP($B9,s!$A:$H,8,0) -> 706317 | S9: =VLOOKUP(B9,total!A:B,2,0) -> 2115823
B10: 45860 | C10: =H54 -> 51000 | D10: =IFERROR(C10/R10,0) -> 0.082944092 | E10: =IFERROR(C10/S10,0) -> 0.026150775 | F10: =VLOOKUP($B10,s!$A:$H,2,0) -> 0.08 | G10: =G54 -> 0.25862069 | H10: =G53 -> 0.051724138 | I10: =VLOOKUP($B10,s!$A:$H,3,0) -> 0.9 | J10: =VLOOKUP($B10,s!$A:$H,4,0) -> 689 | K10: =IFERROR(J10/J9-1,"-") -> -0.10635538 | L10: =AD39 -> 672 | M10: =IFERROR(L10/L9-1,"-") -> -0.065368567 | N10: =AC39 -> 58 | O10: =VLOOKUP($B10,s!$A:$H,5,0) -> 477 | P10: =VLOOKUP($B10,s!$A:$H,6,0) -> 0.38 | Q10: =VLOOKUP($B10,s!$A:$H,7,0) -> 892 | R10: =VLOOKUP($B10,s!$A:$H,8,0) -> 614872 | S10: =VLOOKUP(B10,total!A:B,2,0) -> 1950229
B11: 45867 | C11: =H60 -> 55500 | D11: =IFERROR(C11/R11,0) -> 0.084714847 | E11: =IFERROR(C11/S11,0) -> 0.027847788 | F11: =VLOOKUP($B11,s!$A:$H,2,0) -> 0.06 | G11: =G60 -> 0.28333333 | H11: =G59 -> 0.066666667 | I11: =VLOOKUP($B11,s!$A:$H,3,0) -> 0.89 | J11: =VLOOKUP($B11,s!$A:$H,4,0) -> 749 | K11: =IFERROR(J11/J10-1,"-") -> 0.087082729 | L11: =AG43 -> 720 | M11: =IFERROR(L11/L10-1,"-") -> 0.071428571 | N11: =AF43 -> 60 | O11: =VLOOKUP($B11,s!$A:$H,5,0) -> 532 | P11: =VLOOKUP($B11,s!$A:$H,6,0) -> 0.46 | Q11: =VLOOKUP($B11,s!$A:$H,7,0) -> 875 | R11: =VLOOKUP($B11,s!$A:$H,8,0) -> 655139 | S11: =VLOOKUP(B11,total!A:B,2,0) -> 1992977
B14: dxgy S as is 26.05 (до запуска) | C14: вручений | D14: бонус | E14: доплата за вручение | F14: водители на ступени | G14: SR | J14: Доходимость S 26.05 | M14: Доходимость S 17.06 | P14: Доходимость S 24.06 | S14: Доходимость S 01.07 | V14: Доходимость S 08.07 | Y14: Доходимость S 15.07 | AB14: Доходимость S 22.07 | AE14: Доходимость S 29.07
C15: 10 | F15: 12 | G15: =F15/$K$43 -> 0.22641509 | J15: COUNTA из order_id | K15: COUNTA из executor_profile_id
C16: 15 | F16: 6 | G16: =F16/$K$43 -> 0.11320755 | J16: 1 | K16: 4
C17: 20 | F17: 12 | G17: =F17/$K$43 -> 0.22641509 | J17: 2 | K17: 2
F18: Всего: | G18: =SUM(G15:G17) -> 0.56603774 | J18: 3 | K18: 4
J19: 4 | K19: 2
B20: dxgy S as is 17.06 (1 неделя) | C20: вручений | D20: бонус | E20: доплата за вручение | F20: водители на ступени | G20: SR | H20: Затраты | J20: 6 | K20: 3
C21: 10 | D21: 1700 | E21: =D21/C21 -> 170 | F21: 13 | G21: =F21/$N$41 -> 0.2 | H21: =D21*F21 -> 22100 | J21: 7 | K21: 4
C22: 15 | D22: 3000 | E22: =D22/C22 -> 200 | F22: 6 | G22: =F22/$N$41 -> 0.092307692 | H22: =D22*F22 -> 18000 | J22: 8 | K22: 3
C23: 20 | D23: 4500 | E23: =D23/C23 -> 225 | F23: 10 | G23: =F23/$N$41 -> 0.15384615 | H23: =D23*F23 -> 45000 | J23: 9 | K23: 1
F24: Всего: | G24: =SUM(G21:G23) -> 0.44615385 | H24: =SUM(H21:H23) -> 85100 | J24: 10 | K24: 3
J25: 11 | K25: 4
B26: dxgy S as is 24.06 (2 неделя) | C26: вручений | D26: бонус | E26: доплата за вручение | F26: водители на ступени | G26: SR | H26: Затраты | J26: 12 | K26: 1
C27: 10 | D27: 1700 | E27: =D27/C27 -> 170 | F27: 13 | G27: =F27/$Q$43 -> 0.2 | H27: =D27*F27 -> 22100 | J27: 13 | K27: 3
C28: 15 | D28: 3000 | E28: =D28/C28 -> 200 | F28: 6 | G28: =F28/$Q$43 -> 0.092307692 | H28: =D28*F28 -> 18000 | J28: 14 | K28: 1
C29: 20 | D29: 4500 | E29: =D29/C29 -> 225 | F29: 15 | G29: =F29/$Q$43 -> 0.23076923 | H29: =D29*F29 -> 67500 | J29: 16 | K29: 2
F30: Всего: | G30: =SUM(G27:G29) -> 0.52307692 | H30: =SUM(H27:H29) -> 107600 | J30: 18 | K30: 1
J31: 19 | K31: 3
B32: dxgy S as is 01.07 (3 неделя) | C32: вручений | D32: бонус | E32: доплата за вручение | F32: водители на ступени | G32: SR | H32: Затраты | J32: 20 | K32: 1
C33: 10 | D33: 1700 | E33: =D33/C33 -> 170 | F33: 14 | G33: =F33/$T$43 -> 0.23728814 | H33: =D33*F33 -> 23800 | J33: 21 | K33: 2
C34: 15 | D34: 3000 | E34: =D34/C34 -> 200 | F34: 8 | G34: =F34/$T$43 -> 0.13559322 | H34: =D34*F34 -> 24000 | J34: 24 | K34: 1
C35: 20 | D35: 4500 | E35: =D35/C35 -> 225 | F35: 12 | G35: =F35/$T$43 -> 0.20338983 | H35: =D35*F35 -> 54000 | J35: 25 | K35: 1
F36: Всего: | G36: =SUM(G33:G35) -> 0.57627119 | H36: =SUM(H33:H35) -> 101800 | J36: 27 | K36: 1
J37: 30 | K37: 1
B38: dxgy S as is 08.07 (4 неделя) | C38: вручений | D38: бонус | E38: доплата за вручение | F38: водители на ступени | G38: SR | H38: Затраты | J38: 31 | K38: 1
C39: 10 | D39: 1700 | E39: =D39/C39 -> 170 | F39: 11 | G39: =F39/$W$43 -> 0.2037037 | H39: =D39*F39 -> 18700 | J39: 33 | K39: 1 | AD39: =SUMPRODUCT(AB16:AB38,AC16:AC38) -> 672
C40: 15 | D40: 3000 | E40: =D40/C40 -> 200 | F40: 6 | G40: =F40/$W$43 -> 0.11111111 | H40: =D40*F40 -> 18000 | J40: 34 | K40: 1
C41: 20 | D41: 4500 | E41: =D41/C41 -> 225 | F41: 17 | G41: =F41/$W$43 -> 0.31481481 | H41: =D41*F41 -> 76500 | J41: 45 | K41: 1 | O41: =SUMPRODUCT(M16:M40,N16:N40) -> 710
F42: Всего: | G42: =SUM(G39:G41) -> 0.62962963 | H42: =SUM(H39:H41) -> 113200 | J42: 62 | K42: 1
J43: Итого | K43: 53 | L43: =SUMPRODUCT(J16:J42,K16:K42) -> 726 | R43: =SUMPRODUCT(P16:P42,Q16:Q42) -> 778 | U43: =SUMPRODUCT(S16:S42,T16:T42) -> 847 | X43: =SUMPRODUCT(V16:V42,W16:W42) -> 856 | AA43: =SUMPRODUCT(Y16:Y42,Z16:Z42) -> 719 | AG43: =SUMPRODUCT(AE16:AE42,AF16:AF42) -> 720
...

Sheet опция M2 (ВТ)
C2: Расходы на цели M2 без отсева | G2: Метрики M2
B3: Неделя | C3: sub dxgy | D3: sub dxgy / gmv опции | E3: sub dxgy / gmv total | F3: NI / GMV опции | G3: SR | H3: SR 3 ступени | I3: CDR | J3: Com_del | K3: WoW | L3: Доставки водителей | M3: WoW | N3: Водители | O3: SH active | P3: Utilization | Q3: AVG Fare | R3: GMV | S3: GMV total
B4: 45803 | C4: 0 | D4: =IFERROR(C4/R4,0) -> 0 | E4: =IFERROR(C4/S4,0) -> 0 | F4: =VLOOKUP($B4,'m2'!$A:$H,2,0) -> 0.04 | G4: =G18 -> 0.42857143 | H4: =G17 -> 0 | I4: =VLOOKUP($B4,'m2'!$A:$H,3,0) -> 0.87 | J4: =VLOOKUP($B4,'m2'!$A:$H,4,0) -> 46 | K4: =IFERROR(J4/J3-1,"-") -> - | L4: =L22 -> 101 | M4: =IFERROR(L4/L3-1,"-") -> - | N4: =K22 -> 7 | O4: =VLOOKUP($B4,'m2'!$A:$H,5,0) -> 100 | P4: =VLOOKUP($B4,'m2'!$A:$H,6,0) -> 0.39 | Q4: =VLOOKUP($B4,'m2'!$A:$H,7,0) -> 3107 | R4: =VLOOKUP($B4,'m2'!$A:$H,8,0) -> 142937 | S4: =VLOOKUP(B4,total!A:B,2,0) -> 2023413
B5: 45825 | C5: =H24 -> 14500 | D5: =IFERROR(C5/R5,0) -> 0.10828734 | E5: =IFERROR(C5/S5,0) -> 0.0076011822 | F5: =VLOOKUP($B5,'m2'!$A:$H,2,0) -> 0.01 | G5: =G24 -> 0.28571429 | H5: =G23 -> 0.071428571 | I5: =VLOOKUP($B5,'m2'!$A:$H,3,0) -> 0.77 | J5: =VLOOKUP($B5,'m2'!$A:$H,4,0) -> 44 | K5: =IFERROR(J5/J4-1,"-") -> -0.043478261 | L5: =O27 -> 152 | M5: =IFERROR(L5/L4-1,"-") -> 0.50495049 | N5: =N27 -> 14 | O5: =VLOOKUP($B5,'m2'!$A:$H,5,0) -> 115 | P5: =VLOOKUP($B5,'m2'!$A:$H,6,0) -> 0.41 | Q5: =VLOOKUP($B5,'m2'!$A:$H,7,0) -> 3043 | R5: =VLOOKUP($B5,'m2'!$A:$H,8,0) -> 133903 | S5: =VLOOKUP(B5,total!A:B,2,0) -> 1907598
B6: 45832 | C6: =H30 -> 12500 | D6: =IFERROR(C6/R6,0) -> 0.07802016 | E6: =IFERROR(C6/S6,0) -> 0.0066502521 | F6: =VLOOKUP($B6,'m2'!$A:$H,2,0) -> 0.01 | G6: =G30 -> 0.27272727 | H6: =G29 -> 0.090909091 | I6: =VLOOKUP($B6,'m2'!$A:$H,3,0) -> 0.83 | J6: =VLOOKUP($B6,'m2'!$A:$H,4,0) -> 52 | K6: =IFERROR(J6/J5-1,"-") -> 0.18181818 | L6: =R25 -> 111 | M6: =IFERROR(L6/L5-1,"-") -> -0.26973684 | N6: =Q25 -> 11 | O6: =VLOOKUP($B6,'m2'!$A:$H,5,0) -> 140 | P6: =VLOOKUP($B6,'m2'!$A:$H,6,0) -> 0.35 | Q6: =VLOOKUP($B6,'m2'!$A:$H,7,0) -> 3081 | R6: =VLOOKUP($B6,'m2'!$A:$H,8,0) -> 160215 | S6: =VLOOKUP(B6,total!A:B,2,0) -> 1879628
B7: 45839 | C7: =H36 -> 19000 | D7: =IFERROR(C7/R7,0) -> 0.11072906 | E7: =IFERROR(C7/S7,0) -> 0.0092954854 | F7: =VLOOKUP($B7,'m2'!$A:$H,2,0) -> 0 | G7: =G36 -> 0.30769231 | H7: =G35 -> 0.15384615 | I7: =VLOOKUP($B7,'m2'!$A:$H,3,0) -> 0.79 | J7: =VLOOKUP($B7,'m2'!$A:$H,4,0) -> 57 | K7: =IFERROR(J7/J6-1,"-") -> 0.096153846 | L7: =U25 -> 161 | M7: =IFERROR(L7/L6-1,"-") -> 0.45045045 | N7: =T25 -> 13 | O7: =VLOOKUP($B7,'m2'!$A:$H,5,0) -> 124 | P7: =VLOOKUP($B7,'m2'!$A:$H,6,0) -> 0.41 | Q7: =VLOOKUP($B7,'m2'!$A:$H,7,0) -> 3010 | R7: =VLOOKUP($B7,'m2'!$A:$H,8,0) -> 171590 | S7: =VLOOKUP(B7,total!A:B,2,0) -> 2044003
B8: 45846 | C8: =H42 -> 19000 | D8: =IFERROR(C8/R8,0) -> 0.1351015 | E8: =IFERROR(C8/S8,0) -> 0.0088071462 | F8: =VLOOKUP($B8,'m2'!$A:$H,2,0) -> 0 | G8: =G42 -> 0.8 | H8: =G41 -> 0.4 | I8: =VLOOKUP($B8,'m2'!$A:$H,3,0) -> 0.77 | J8: =VLOOKUP($B8,'m2'!$A:$H,4,0) -> 48 | K8: =IFERROR(J8/J7-1,"-") -> -0.15789474 | L8: =X21 -> 106 | M8: =IFERROR(L8/L7-1,"-") -> -0.34161491 | N8: =W21 -> 5 | O8: =VLOOKUP($B8,'m2'!$A:$H,5,0) -> 111 | P8: =VLOOKUP($B8,'m2'!$A:$H,6,0) -> 0.58 | Q8: =VLOOKUP($B8,'m2'!$A:$H,7,0) -> 2930 | R8: =VLOOKUP($B8,'m2'!$A:$H,8,0) -> 140635 | S8: =VLOOKUP(B8,total!A:B,2,0) -> 2157339
B9: 45853 | C9: =H48 -> 26000 | D9: =IFERROR(C9/R9,0) -> 0.15536765 | E9: =IFERROR(C9/S9,0) -> 0.012288363 | F9: =VLOOKUP($B9,'m2'!$A:$H,2,0) -> 0.01 | G9: =G48 -> 0.45454545 | H9: =G47 -> 0.36363636 | I9: =VLOOKUP($B9,'m2'!$A:$H,3,0) -> 0.81 | J9: =VLOOKUP($B9,'m2'!$A:$H,4,0) -> 66 | K9: =IFERROR(J9/J8-1,"-") -> 0.375 | L9: =AA25 -> 171 | M9: =IFERROR(L9/L8-1,"-") -> 0.61320755 | N9: =Z25 -> 11 | O9: =VLOOKUP($B9,'m2'!$A:$H,5,0) -> 130 | P9: =VLOOKUP($B9,'m2'!$A:$H,6,0) -> 0.51 | Q9: =VLOOKUP($B9,'m2'!$A:$H,7,0) -> 2536 | R9: =VLOOKUP($B9,'m2'!$A:$H,8,0) -> 167345 | S9: =VLOOKUP(B9,total!A:B,2,0) -> 2115823
B10: 45860 | C10: =H54 -> 22000 | D10: =IFERROR(C10/R10,0) -> 0.18860322 | E10: =IFERROR(C10/S10,0) -> 0.011280727 | F10: =VLOOKUP($B10,'m2'!$A:$H,2,0) -> 0.03 | G10: =G54 -> 0.45454545 | H10: =G53 -> 0 | I10: =VLOOKUP($B10,'m2'!$A:$H,3,0) -> 0.68 | J10: =VLOOKUP($B10,'m2'!$A:$H,4,0) -> 42 | K10: =IFERROR(J10/J9-1,"-") -> -0.36363636 | L10: =AD24 -> 141 | M10: =IFERROR(L10/L9-1,"-") -> -0.1754386 | N10: =AC24 -> 11 | O10: =VLOOKUP($B10,'m2'!$A:$H,5,0) -> 112 | P10: =VLOOKUP($B10,'m2'!$A:$H,6,0) -> 0.48 | Q10: =VLOOKUP($B10,'m2'!$A:$H,7,0) -> 2777 | R10: =VLOOKUP($B10,'m2'!$A:$H,8,0) -> 116647 | S10: =VLOOKUP(B10,total!A:B,2,0) -> 1950229
B11: 45867 | C11: =H60 -> 26000 | D11: =IFERROR(C11/R11,0) -> 0.18608513 | E11: =IFERROR(C11/S11,0) -> 0.01304581 | F11: =VLOOKUP($B11,'m2'!$A:$H,2,0) -> 0 | G11: =G60 -> 0.71428571 | H11: =G59 -> 0.28571429 | I11: =VLOOKUP($B11,'m2'!$A:$H,3,0) -> 0.72 | J11: =VLOOKUP($B11,'m2'!$A:$H,4,0) -> 51 | K11: =IFERROR(J11/J10-1,"-") -> 0.21428571 | L11: =AG23 -> 135 | M11: =IFERROR(L11/L10-1,"-") -> -0.042553191 | N11: =AF23 -> 7 | O11: =VLOOKUP($B11,'m2'!$A:$H,5,0) -> 136 | P11: =VLOOKUP($B11,'m2'!$A:$H,6,0) -> 0.57 | Q11: =VLOOKUP($B11,'m2'!$A:$H,7,0) -> 2740 | R11: =VLOOKUP($B11,'m2'!$A:$H,8,0) -> 139721 | S11: =VLOOKUP(B11,total!A:B,2,0) -> 1992977
B14: dxgy M2 as is 26.05 (до запуска) | C14: вручений | D14: бонус | E14: доплата за вручение | F14: водители на ступени | G14: SR | J14: Доходимость M2 26.05 | M14: Доходимость M2 17.06 | P14: Доходимость M2 24.06 | S14: Доходимость M2 01.07 | V14: Доходимость M2 08.07 | Y14: Доходимость M2 15.07 | AB14: Доходимость M2 22.07 | AE14: Доходимость M2 29.07
C15: 16 | F15: 2 | G15: =F15/$K$22 -> 0.28571429 | J15: COUNTA из order_id | K15: COUNTA из executor_profile_id
C16: 20 | F16: 1 | G16: =F16/$K$22 -> 0.14285714 | J16: 9 | K16: 1
C17: 24 | F17: 0 | G17: =F17/$K$22 -> 0 | J17: 10 | K17: 1
F18: Всего: | G18: =SUM(G15:G17) -> 0.42857143 | J18: 12 | K18: 1
J19: 15 | K19: 1
B20: dxgy M2 as is 17.06 (1 неделя) | C20: вручений | D20: бонус | E20: доплата за вручение | F20: водители на ступени | G20: SR | H20: Затраты | J20: 16 | K20: 2
C21: 16 | D21: 3000 | E21: =D21/C21 -> 187.5 | F21: 3 | G21: =F21/$N$27 -> 0.21428571 | H21: =D21*F21 -> 9000 | J21: 23 | K21: 1 | X21: =SUMPRODUCT(V16:V20,W16:W20) -> 106
C22: 20 | D22: 4000 | E22: =D22/C22 -> 200 | F22: 0 | G22: =F22/$N$27 -> 0 | H22: =D22*F22 -> 0 | J22: Итого | K22: 7 | L22: =SUMPRODUCT(J16:J21,K16:K21) -> 101
C23: 24 | D23: 5500 | E23: =D23/C23 -> 229.16667 | F23: 1 | G23: =F23/$N$27 -> 0.071428571 | H23: =D23*F23 -> 5500 | AG23: =SUMPRODUCT(AE15:AE22,AF15:AF22) -> 135
F24: Всего: | G24: =SUM(G21:G23) -> 0.28571429 | H24: =SUM(H21:H23) -> 14500 | AD24: =SUMPRODUCT(AB16:AB23,AC16:AC23) -> 141
R25: =SUMPRODUCT(P16:P24,Q16:Q24) -> 111 | U25: =SUMPRODUCT(S16:S24,T16:T24) -> 161 | AA25: =SUMPRODUCT(Y16:Y24,Z16:Z24) -> 171
B26: dxgy M2 as is 24.06 (2 неделя) | C26: вручений | D26: бонус | E26: доплата за вручение | F26: водители на ступени | G26: SR | H26: Затраты
C27: 16 | D27: 3000 | E27: =D27/C27 -> 187.5 | F27: 1 | G27: =F27/$Q$25 -> 0.090909091 | H27: =D27*F27 -> 3000 | O27: =SUMPRODUCT(M16:M26,N16:N26) -> 152
C28: 20 | D28: 4000 | E28: =D28/C28 -> 200 | F28: 1 | G28: =F28/$Q$25 -> 0.090909091 | H28: =D28*F28 -> 4000
C29: 24 | D29: 5500 | E29: =D29/C29 -> 229.16667 | F29: 1 | G29: =F29/$Q$25 -> 0.090909091 | H29: =D29*F29 -> 5500
F30: Всего: | G30: =SUM(G27:G29) -> 0.27272727 | H30: =SUM(H27:H29) -> 12500
B32: dxgy M2 as is 01.07 (3 неделя) | C32: вручений | D32: бонус | E32: доплата за вручение | F32: водители на ступени | G32: SR | H32: Затраты
C33: 16 | D33: 3000 | E33: =D33/C33 -> 187.5 | F33: 0 | G33: =F33/$T$25 -> 0 | H33: =D33*F33 -> 0
C34: 20 | D34: 4000 | E34: =D34/C34 -> 200 | F34: 2 | G34: =F34/$T$25 -> 0.15384615 | H34: =D34*F34 -> 8000
C35: 24 | D35: 5500 | E35: =D35/C35 -> 229.16667 | F35: 2 | G35: =F35/$T$25 -> 0.15384615 | H35: =D35*F35 -> 11000
F36: Всего: | G36: =SUM(G33:G35) -> 0.30769231 | H36: =SUM(H33:H35) -> 19000
B38: dxgy M2 as is 08.07 (4 неделя) | C38: вручений | D38: бонус | E38: доплата за вручение | F38: водители на ступени | G38: SR | H38: Затраты
C39: 16 | D39: 3000 | E39: =D39/C39 -> 187.5 | F39: 0 | G39: =F39/$N$8 -> 0 | H39: =D39*F39 -> 0
C40: 20 | D40: 4000 | E40: =D40/C40 -> 200 | F40: 2 | G40: =F40/$N$8 -> 0.4 | H40: =D40*F40 -> 8000
C41: 24 | D41: 5500 | E41: =D41/C41 -> 229.16667 | F41: 2 | G41: =F41/$N$8 -> 0.4 | H41: =D41*F41 -> 11000
F42: Всего: | G42: =SUM(G39:G41) -> 0.8 | H42: =SUM(H39:H41) -> 19000
B44: dxgy M2 as is 15.07 (5 неделя) | C44: вручений | D44: бонус | E44: доплата за вручение | F44: водители на ступени | G44: SR | H44: Затраты
C45: 16 | D45: 3000 | E45: =D45/C45 -> 187.5 | F45: 0 | G45: =F45/$N$9 -> 0 | H45: =D45*F45 -> 0
C46: 20 | D46: 4000 | E46: =D46/C46 -> 200 | F46: 1 | G46: =F46/$N$9 -> 0.090909091 | H46: =D46*F46 -> 4000
...

Sheet кузов L (ВТ)
C2: Расходы на цели L без отсева | G2: Метрики L
B3: Неделя | C3: sub dxgy | D3: sub dxgy / gmv опции | E3: sub dxgy / gmv total | F3: NI / GMV опции | G3: SR | H3: SR 3 ступени | I3: CDR | J3: Com_del | K3: WoW | L3: Доставки водителей | M3: WoW | N3: Водители | O3: SH active | P3: Utilization | Q3: AVG Fare | R3: GMV | S3: GMV total
B4: 45803 | C4: 0 | D4: =IFERROR(C4/R4,0) -> 0 | E4: =IFERROR(C4/S4,0) -> 0 | F4: =VLOOKUP($B4,l!$A:$H,2,0) -> 0.17 | G4: =G18 -> 0.21818182 | H4: =G17 -> 0.10909091 | I4: =VLOOKUP($B4,l!$A:$H,3,0) -> 0.81 | J4: =VLOOKUP($B4,l!$A:$H,4,0) -> 316 | K4: =IFERROR(J4/J3-1,"-") -> - | L4: =L37 -> 433 | M4: =IFERROR(L4/L3-1,"-") -> - | N4: =K37 -> 55 | O4: =VLOOKUP($B4,l!$A:$H,5,0) -> 413 | P4: =VLOOKUP($B4,l!$A:$H,6,0) -> 0.4 | Q4: =VLOOKUP($B4,l!$A:$H,7,0) -> 1391 | R4: =VLOOKUP($B4,l!$A:$H,8,0) -> 439427 | S4: =VLOOKUP(B4,total!A:B,2,0) -> 2023413
B5: 45825 | C5: =H24 -> 33300 | D5: =IFERROR(C5/R5,0) -> 0.082477189 | E5: =IFERROR(C5/S5,0) -> 0.017456508 | F5: =VLOOKUP($B5,l!$A:$H,2,0) -> 0.12 | G5: =G24 -> 0.26530612 | H5: =G23 -> 0.081632653 | I5: =VLOOKUP($B5,l!$A:$H,3,0) -> 0.86 | J5: =VLOOKUP($B5,l!$A:$H,4,0) -> 271 | K5: =IFERROR(J5/J4-1,"-") -> -0.14240506 | L5: =O34 -> 365 | M5: =IFERROR(L5/L4-1,"-") -> -0.15704388 | N5: =N34 -> 49 | O5: =VLOOKUP($B5,l!$A:$H,5,0) -> 324 | P5: =VLOOKUP($B5,l!$A:$H,6,0) -> 0.45 | Q5: =VLOOKUP($B5,l!$A:$H,7,0) -> 1490 | R5: =VLOOKUP($B5,l!$A:$H,8,0) -> 403748 | S5: =VLOOKUP(B5,total!A:B,2,0) -> 1907598
B6: 45832 | C6: =H30 -> 39300 | D6: =IFERROR(C6/R6,0) -> 0.11177125 | E6: =IFERROR(C6/S6,0) -> 0.020908393 | F6: =VLOOKUP($B6,l!$A:$H,2,0) -> 0.07 | G6: =G30 -> 0.38888889 | H6: =G29 -> 0.13888889 | I6: =VLOOKUP($B6,l!$A:$H,3,0) -> 0.85 | J6: =VLOOKUP($B6,l!$A:$H,4,0) -> 251 | K6: =IFERROR(J6/J5-1,"-") -> -0.073800738 | L6: =R33 -> 354 | M6: =IFERROR(L6/L5-1,"-") -> -0.030136986 | N6: =Q33 -> 36 | O6: =VLOOKUP($B6,l!$A:$H,5,0) -> 339 | P6: =VLOOKUP($B6,l!$A:$H,6,0) -> 0.3 | Q6: =VLOOKUP($B6,l!$A:$H,7,0) -> 1401 | R6: =VLOOKUP($B6,l!$A:$H,8,0) -> 351611 | S6: =VLOOKUP(B6,total!A:B,2,0) -> 1879628
B7: 45839 | C7: =H36 -> 33700 | D7: =IFERROR(C7/R7,0) -> 0.09379166 | E7: =IFERROR(C7/S7,0) -> 0.016487256 | F7: =VLOOKUP($B7,l!$A:$H,2,0) -> 0.08 | G7: =G36 -> 0.37837838 | H7: =G35 -> 0.081081081 | I7: =VLOOKUP($B7,l!$A:$H,3,0) -> 0.82 | J7: =VLOOKUP($B7,l!$A:$H,4,0) -> 253 | K7: =IFERROR(J7/J6-1,"-") -> 0.0079681275 | L7: =U36 -> 369 | M7: =IFERROR(L7/L6-1,"-") -> 0.042372881 | N7: =T36 -> 37 | O7: =VLOOKUP($B7,l!$A:$H,5,0) -> 336 | P7: =VLOOKUP($B7,l!$A:$H,6,0) -> 0.37 | Q7: =VLOOKUP($B7,l!$A:$H,7,0) -> 1420 | R7: =VLOOKUP($B7,l!$A:$H,8,0) -> 359307 | S7: =VLOOKUP(B7,total!A:B,2,0) -> 2044003
B8: 45846 | C8: =H42 -> 36200 | D8: =IFERROR(C8/R8,0) -> 0.1005469 | E8: =IFERROR(C8/S8,0) -> 0.016779931 | F8: =VLOOKUP($B8,l!$A:$H,2,0) -> 0.1 | G8: =G42 -> 0.32432432 | H8: =G41 -> 0.16216216 | I8: =VLOOKUP($B8,l!$A:$H,3,0) -> 0.79 | J8: =VLOOKUP($B8,l!$A:$H,4,0) -> 244 | K8: =IFERROR(J8/J7-1,"-") -> -0.035573123 | L8: =X37 -> 370 | M8: =IFERROR(L8/L7-1,"-") -> 0.0027100271 | N8: =W37 -> 37 | O8: =VLOOKUP($B8,l!$A:$H,5,0) -> 348 | P8: =VLOOKUP($B8,l!$A:$H,6,0) -> 0.47 | Q8: =VLOOKUP($B8,l!$A:$H,7,0) -> 1476 | R8: =VLOOKUP($B8,l!$A:$H,8,0) -> 360031 | S8: =VLOOKUP(B8,total!A:B,2,0) -> 2157339
B9: 45853 | C9: =H48 -> 36200 | D9: =IFERROR(C9/R9,0) -> 0.099019922 | E9: =IFERROR(C9/S9,0) -> 0.017109182 | F9: =VLOOKUP($B9,l!$A:$H,2,0) -> 0.12 | G9: =G48 -> 0.3 | H9: =G47 -> 0.15 | I9: =VLOOKUP($B9,l!$A:$H,3,0) -> 0.82 | J9: =VLOOKUP($B9,l!$A:$H,4,0) -> 248 | K9: =IFERROR(J9/J8-1,"-") -> 0.016393443 | L9: =AA36 -> 372 | M9: =IFERROR(L9/L8-1,"-") -> 0.0054054054 | N9: =Z36 -> 40 | O9: =VLOOKUP($B9,l!$A:$H,5,0) -> 351 | P9: =VLOOKUP($B9,l!$A:$H,6,0) -> 0.46 | Q9: =VLOOKUP($B9,l!$A:$H,7,0) -> 1474 | R9: =VLOOKUP($B9,l!$A:$H,8,0) -> 365583 | S9: =VLOOKUP(B9,total!A:B,2,0) -> 2115823
B10: 45860 | C10: =H54 -> 43600 | D10: =IFERROR(C10/R10,0) -> 0.099130336 | E10: =IFERROR(C10/S10,0) -> 0.022356349 | F10: =VLOOKUP($B10,l!$A:$H,2,0) -> 0.1 | G10: =G54 -> 0.26086957 | H10: =G53 -> 0.086956522 | I10: =VLOOKUP($B10,l!$A:$H,3,0) -> 0.89 | J10: =VLOOKUP($B10,l!$A:$H,4,0) -> 318 | K10: =IFERROR(J10/J9-1,"-") -> 0.28225806 | L10: =AD33 -> 406 | M10: =IFERROR(L10/L9-1,"-") -> 0.091397849 | N10: =AC33 -> 46 | O10: =VLOOKUP($B10,l!$A:$H,5,0) -> 362 | P10: =VLOOKUP($B10,l!$A:$H,6,0) -> 0.48 | Q10: =VLOOKUP($B10,l!$A:$H,7,0) -> 1383 | R10: =VLOOKUP($B10,l!$A:$H,8,0) -> 439825 | S10: =VLOOKUP(B10,total!A:B,2,0) -> 1950229
B11: 45867 | C11: =H60 -> 37400 | D11: =IFERROR(C11/R11,0) -> 0.10578718 | E11: =IFERROR(C11/S11,0) -> 0.018765896 | F11: =VLOOKUP($B11,l!$A:$H,2,0) -> 0.07 | G11: =G60 -> 0.24324324 | H11: =G59 -> 0.13513514 | I11: =VLOOKUP($B11,l!$A:$H,3,0) -> 0.76 | J11: =VLOOKUP($B11,l!$A:$H,4,0) -> 244 | K11: =IFERROR(J11/J10-1,"-") -> -0.2327044 | L11: =AG35 -> 375 | M11: =IFERROR(L11/L10-1,"-") -> -0.07635468 | N11: =AF35 -> 37 | O11: =VLOOKUP($B11,l!$A:$H,5,0) -> 314 | P11: =VLOOKUP($B11,l!$A:$H,6,0) -> 0.44 | Q11: =VLOOKUP($B11,l!$A:$H,7,0) -> 1449 | R11: =VLOOKUP($B11,l!$A:$H,8,0) -> 353540 | S11: =VLOOKUP(B11,total!A:B,2,0) -> 1992977
B14: dxgy L as is 26.05 (до запуска) | C14: вручений | D14: бонус | E14: доплата за вручение | F14: водители на ступени | G14: SR | J14: Доходимость L 26.05 | M14: Доходимость L 17.06 | P14: Доходимость L 24.06 | S14: Доходимость L 01.07 | V14: Доходимость L 08.07 | Y14: Доходимость L 15.07 | AB14: Доходимость L 22.07 | AE14: Доходимость L 29.07
C15: 12 | F15: 5 | G15: =F15/$K$37 -> 0.090909091 | J15: COUNTA из order_id | K15: COUNTA из executor_profile_id
C16: 17 | F16: 1 | G16: =F16/$K$37 -> 0.018181818 | J16: 1 | K16: 11
C17: 22 | F17: 6 | G17: =F17/$K$37 -> 0.10909091 | J17: 2 | K17: 5
F18: Всего: | G18: =SUM(G15:G17) -> 0.21818182 | J18: 3 | K18: 5
J19: 4 | K19: 4
B20: dxgy L as is 17.06 (1 неделя) | C20: вручений | D20: бонус | E20: доплата за вручение | F20: водители на ступени | G20: SR | H20: Затраты | J20: 5 | K20: 3
C21: 12 | D21: 1700 | E21: =D21/C21 -> 141.66667 | F21: 7 | G21: =F21/$N$34 -> 0.14285714 | H21: =D21*F21 -> 11900 | J21: 6 | K21: 8
C22: 17 | D22: 2700 | E22: =D22/C22 -> 158.82353 | F22: 2 | G22: =F22/$N$34 -> 0.040816327 | H22: =D22*F22 -> 5400 | J22: 7 | K22: 2
C23: 22 | D23: 4000 | E23: =D23/C23 -> 181.81818 | F23: 4 | G23: =F23/$N$34 -> 0.081632653 | H23: =D23*F23 -> 16000 | J23: 8 | K23: 2
F24: Всего: | G24: =SUM(G21:G23) -> 0.26530612 | H24: =SUM(H21:H23) -> 33300 | J24: 9 | K24: 1
J25: 10 | K25: 2
B26: dxgy L as is 24.06 (2 неделя) | C26: вручений | D26: бонус | E26: доплата за вручение | F26: водители на ступени | G26: SR | H26: Затраты | J26: 12 | K26: 2
C27: 12 | D27: 1700 | E27: =D27/C27 -> 141.66667 | F27: 5 | G27: =F27/$Q$33 -> 0.13888889 | H27: =D27*F27 -> 8500 | J27: 14 | K27: 1
C28: 17 | D28: 2700 | E28: =D28/C28 -> 158.82353 | F28: 4 | G28: =F28/$Q$33 -> 0.11111111 | H28: =D28*F28 -> 10800 | J28: 15 | K28: 1
C29: 22 | D29: 4000 | E29: =D29/C29 -> 181.81818 | F29: 5 | G29: =F29/$Q$33 -> 0.13888889 | H29: =D29*F29 -> 20000 | J29: 16 | K29: 1
F30: Всего: | G30: =SUM(G27:G29) -> 0.38888889 | H30: =SUM(H27:H29) -> 39300 | J30: 19 | K30: 1
J31: 22 | K31: 1
B32: dxgy L as is 01.07 (3 неделя) | C32: вручений | D32: бонус | E32: доплата за вручение | F32: водители на ступени | G32: SR | H32: Затраты | J32: 25 | K32: 1
C33: 12 | D33: 1700 | E33: =D33/C33 -> 141.66667 | F33: 8 | G33: =F33/$T$36 -> 0.21621622 | H33: =D33*F33 -> 13600 | J33: 28 | K33: 1 | R33: =SUMPRODUCT(P16:P32,Q16:Q32) -> 354 | AD33: =SUMPRODUCT(AB16:AB32,AC16:AC32) -> 406
C34: 17 | D34: 2700 | E34: =D34/C34 -> 158.82353 | F34: 3 | G34: =F34/$T$36 -> 0.081081081 | H34: =D34*F34 -> 8100 | J34: 29 | K34: 1 | O34: =SUMPRODUCT(M16:M33,N16:N33) -> 365
C35: 22 | D35: 4000 | E35: =D35/C35 -> 181.81818 | F35: 3 | G35: =F35/$T$36 -> 0.081081081 | H35: =D35*F35 -> 12000 | J35: 32 | K35: 1 | AG35: =SUMPRODUCT(AE15:AE34,AF15:AF34) -> 375
F36: Всего: | G36: =SUM(G33:G35) -> 0.37837838 | H36: =SUM(H33:H35) -> 33700 | J36: 35 | K36: 1 | U36: =SUMPRODUCT(S16:S35,T16:T35) -> 369 | AA36: =SUMPRODUCT(Y16:Y35,Z16:Z35) -> 372
J37: Итого | K37: 55 | L37: =SUMPRODUCT(J16:J36,K16:K36) -> 433 | X37: =SUMPRODUCT(V16:V36,W16:W36) -> 370
B38: dxgy L as is 08.07 (4 неделя) | C38: вручений | D38: бонус | E38: доплата за вручение | F38: водители на ступени | G38: SR | H38: Затраты
C39: 12 | D39: 1700 | E39: =D39/C39 -> 141.66667 | F39: 4 | G39: =F39/$W$37 -> 0.10810811 | H39: =D39*F39 -> 6800
C40: 17 | D40: 2700 | E40: =D40/C40 -> 158.82353 | F40: 2 | G40: =F40/$W$37 -> 0.054054054 | H40: =D40*F40 -> 5400
C41: 22 | D41: 4000 | E41: =D41/C41 -> 181.81818 | F41: 6 | G41: =F41/$W$37 -> 0.16216216 | H41: =D41*F41 -> 24000
F42: Всего: | G42: =SUM(G39:G41) -> 0.32432432 | H42: =SUM(H39:H41) -> 36200
B44: dxgy L as is 15.07 (5 неделя) | C44: вручений | D44: бонус | E44: доплата за вручение | F44: водители на ступени | G44: SR | H44: Затраты
...

Sheet total
A1: неделя | B1: GMV
A2: 45803 | B2: 2023413
A3: 45825 | B3: 1907598
A4: 45832 | B4: 1879628
A5: 45839 | B5: 2044003
A6: 45846 | B6: 2157339
A7: 45853 | B7: 2115823
A8: 45860 | B8: 1950229
A9: 45867 | B9: 1992977

Sheet s
A1: неделя | B1: NI/GMV | C1: CDR | D1: Com_del | E1: SH active | F1: Utilization | G1: AVG fare | H1: GMV
A2: 45803 | B2: 0.17 | C2: 0.85 | D2: 782 | E2: 481 | F2: 0.41 | G2: 821 | H2: 642405
A3: 45825 | B3: 0.07 | C3: 0.91 | D3: 731 | E3: 560 | F3: 0.39 | G3: 864 | H3: 631927
A4: 45832 | B4: 0.02 | C4: 0.9 | D4: 830 | E4: 551 | F4: 0.4 | G4: 757 | H4: 628042
A5: 45839 | B5: 0.02 | C5: 0.92 | D5: 875 | E5: 565 | F5: 0.41 | G5: 793 | H5: 694259
A6: 45846 | B6: 0.05 | C6: 0.86 | D6: 912 | E6: 610 | F6: 0.61 | G6: 881 | H6: 803114
A7: 45853 | B7: 0.04 | C7: 0.87 | D7: 771 | E7: 535 | F7: 0.49 | G7: 916 | H7: 706317
A8: 45860 | B8: 0.08 | C8: 0.9 | D8: 689 | E8: 477 | F8: 0.38 | G8: 892 | H8: 614872
A9: 45867 | B9: 0.06 | C9: 0.89 | D9: 749 | E9: 532 | F9: 0.46 | G9: 875 | H9: 655139

Sheet m2
A1: неделя | B1: NI/GMV | C1: CDR | D1: Com_del | E1: SH active | F1: Utilization | G1: AVG fare | H1: GMV
A2: 45803 | B2: 0.04 | C2: 0.87 | D2: 46 | E2: 100 | F2: 0.39 | G2: 3107 | H2: 142937
A3: 45825 | B3: 0.01 | C3: 0.77 | D3: 44 | E3: 115 | F3: 0.41 | G3: 3043 | H3: 133903
A4: 45832 | B4: 0.01 | C4: 0.83 | D4: 52 | E4: 140 | F4: 0.35 | G4: 3081 | H4: 160215
A5: 45839 | B5: 0 | C5: 0.79 | D5: 57 | E5: 124 | F5: 0.41 | G5: 3010 | H5: 171590
A6: 45846 | B6: 0 | C6: 0.77 | D6: 48 | E6: 111 | F6: 0.58 | G6: 2930 | H6: 140635
A7: 45853 | B7: 0.01 | C7: 0.81 | D7: 66 | E7: 130 | F7: 0.51 | G7: 2536 | H7: 167345
A8: 45860 | B8: 0.03 | C8: 0.68 | D8: 42 | E8: 112 | F8: 0.48 | G8: 2777 | H8: 116647
A9: 45867 | B9: 0 | C9: 0.72 | D9: 51 | E9: 136 | F9: 0.57 | G9: 2740 | H9: 139721

Sheet l
A1: неделя | B1: NI/GMV | C1: CDR | D1: Com_del | E1: SH active | F1: Utilization | G1: AVG fare | H1: GMV
A2: 45803 | B2: 0.17 | C2: 0.81 | D2: 316 | E2: 413 | F2: 0.4 | G2: 1391 | H2: 439427
A3: 45825 | B3: 0.12 | C3: 0.86 | D3: 271 | E3: 324 | F3: 0.45 | G3: 1490 | H3: 403748
A4: 45832 | B4: 0.07 | C4: 0.85 | D4: 251 | E4: 339 | F4: 0.3 | G4: 1401 | H4: 351611
A5: 45839 | B5: 0.08 | C5: 0.82 | D5: 253 | E5: 336 | F5: 0.37 | G5: 1420 | H5: 359307
A6: 45846 | B6: 0.1 | C6: 0.79 | D6: 244 | E6: 348 | F6: 0.47 | G6: 1476 | H6: 360031
A7: 45853 | B7: 0.12 | C7: 0.82 | D7: 248 | E7: 351 | F7: 0.46 | G7: 1474 | H7: 365583
A8: 45860 | B8: 0.1 | C8: 0.89 | D8: 318 | E8: 362 | F8: 0.48 | G8: 1383 | H8: 439825
A9: 45867 | B9: 0.07 | C9: 0.76 | D9: 244 | E9: 314 | F9: 0.44 | G9: 1449 | H9: 353540

Sheet доставки 29.07
A1: local date | B1: order_id | C1: executor_profile_id | D1: cargo size & loaders
A2: 45873 | B2: cargo_39891ae96832409cbe8cacd339185323 | C2: 82bda94685b241c888df48879f9ddeb3 | D2: lcv_m_0 | S2: Опция
A3: 45873 | B3: cargo_42962cf3212a4fada6f2128e6e217bda | C3: f3532d94ec0744f89ed49346e10f2cbd | D3: lcv_m_0 | S3: =IF(H3>0,"L1",IF(G3>0,"L0",IF(L3>0,"M2",IF(K3>0,"M1",IF(J3>0,"M0",IF(P3>0,"S2",IF(O3>0,"S1","S0"))))))) -> L0
A4: 45873 | B4: cargo_242c45e9517d490e8d342896b0382868 | C4: a14c4efc794747ac86f0c6685e8e5365 | D4: lcv_m_0 | S4: =IF(H4>0,"L1",IF(G4>0,"L0",IF(L4>0,"M2",IF(K4>0,"M1",IF(J4>0,"M0",IF(P4>0,"S2",IF(O4>0,"S1","S0"))))))) -> M0
A5: 45873 | B5: cargo_9e0ab127849a4cc48d60684c2a91c92f | C5: 3eb70a68dd2745c5bdc158b70affea51 | D5: lcv_l_0 | S5: =IF(H5>0,"L1",IF(G5>0,"L0",IF(L5>0,"M2",IF(K5>0,"M1",IF(J5>0,"M0",IF(P5>0,"S2",IF(O5>0,"S1","S0"))))))) -> M0
A6: 45873 | B6: cargo_bbbcd3d36c4449cb9fb9e2c4c7659a0b | C6: 4838f63fd4cb42789463e2f7fa84bb9b | D6: van_0 | S6: =IF(H6>0,"L1",IF(G6>0,"L0",IF(L6>0,"M2",IF(K6>0,"M1",IF(J6>0,"M0",IF(P6>0,"S2",IF(O6>0,"S1","S0"))))))) -> S0
A7: 45873 | B7: cargo_6d772605d90a4651a2d62b037b21a396 | C7: a103be4aaace48cf97e23645d176dd15 | D7: van_0 | S7: =IF(H7>0,"L1",IF(G7>0,"L0",IF(L7>0,"M2",IF(K7>0,"M1",IF(J7>0,"M0",IF(P7>0,"S2",IF(O7>0,"S1","S0"))))))) -> L1
A8: 45873 | B8: cargo_05d1fb91aca44dafa3eadcb11ae7e5a9 | C8: 3e5fec28a9044189b707a7ef40ec993c | D8: van_0 | S8: =IF(H8>0,"L1",IF(G8>0,"L0",IF(L8>0,"M2",IF(K8>0,"M1",IF(J8>0,"M0",IF(P8>0,"S2",IF(O8>0,"S1","S0"))))))) -> L0
A9: 45873 | B9: cargo_bd38d7c01e0a438baeb37ea499655cda | C9: 60e169bdabda4f0b882c10bc87d1fdd4 | D9: lcv_m_0 | S9: =IF(H9>0,"L1",IF(G9>0,"L0",IF(L9>0,"M2",IF(K9>0,"M1",IF(J9>0,"M0",IF(P9>0,"S2",IF(O9>0,"S1","S0"))))))) -> S1
A10: 45873 | B10: cargo_7da1c6c0884f491fbb2144b8168d4325 | C10: 9aa1cb963e2b49bc86aaa82e55fc611c | D10: lcv_l_0 | S10: =IF(H10>0,"L1",IF(G10>0,"L0",IF(L10>0,"M2",IF(K10>0,"M1",IF(J10>0,"M0",IF(P10>0,"S2",IF(O10>0,"S1","S0"))))))) -> M1
A11: 45873 | B11: cargo_559f64cca4cf4947bcd7a9ce2a02a938 | C11: e6556175182544e7b7d8a00276bd4d6a | D11: lcv_m_0 | S11: =IF(H11>0,"L1",IF(G11>0,"L0",IF(L11>0,"M2",IF(K11>0,"M1",IF(J11>0,"M0",IF(P11>0,"S2",IF(O11>0,"S1","S0"))))))) -> S0
A12: 45873 | B12: cargo_39109d6f4e604dc684f200106a95257d | C12: c6a2c4a6a16eaab8f17c68c475ab723f | D12: van_0 | S12: =IF(H12>0,"L1",IF(G12>0,"L0",IF(L12>0,"M2",IF(K12>0,"M1",IF(J12>0,"M0",IF(P12>0,"S2",IF(O12>0,"S1","S0"))))))) -> S1
A13: 45873 | B13: cargo_4d0d90a984eb478c8a6f174fc9b53ece | C13: 3eb70a68dd2745c5bdc158b70affea51 | D13: lcv_l_0 | S13: =IF(H13>0,"L1",IF(G13>0,"L0",IF(L13>0,"M2",IF(K13>0,"M1",IF(J13>0,"M0",IF(P13>0,"S2",IF(O13>0,"S1","S0"))))))) -> S0
A14: 45873 | B14: cargo_2a3e5d3768f946dc851e5d19ad45d32b | C14: e5996b4048cc48f48366966fe76cbaa4 | D14: van_X_loaders | S14: =IF(H14>0,"L1",IF(G14>0,"L0",IF(L14>0,"M2",IF(K14>0,"M1",IF(J14>0,"M0",IF(P14>0,"S2",IF(O14>0,"S1","S0"))))))) -> L0
... A172: 45873 | B172: cargo_3b907163be84443b9158402dad6f01c0 | C172: 591de50eccc54ee284238f494ff60b31 | D172: lcv_m_1 | S172: =IF(H172>0,"L1",IF(G172>0,"L0",IF(L172>0,"M2",IF(K172>0,"M1",IF(J172>0,"M0",IF(P172>0,"S2",IF(O172>0,"S1","S0"))))))) -> L1
A173: 45873 | B173: cargo_42274136bd2b4bb587a6776c354fcf56 | C173: f844ec8249544474bab6e405172651f5 | D173: lcv_l_0
A174: 45873 | B174: cargo_8c00d4cbec2f4346bf2aa29ceac8d383 | C174: f844ec8249544474bab6e405172651f5 | D174: lcv_m_0
A175: 45873 | B175: cargo_223b9225cbde42fa9914273b300c529b | C175: eabaf0d964b2cb4bc35732e00373e9bb | D175: lcv_m_0
A176: 45873 | B176: cargo_e8b18f2969834737966984b332659c91 | C176: 2d196adb18c5459f8e8ba27300368da2 | D176: lcv_m_0
A177: 45873 | B177: cargo_a818d2861fc2434e878958034e0e87c9 | C177: a40d4ff06d294ebdbf79f4211a1f99b0 | D177: van_0
A178: 45873 | B178: cargo_2711d0e0dd6a4492a98eac65dea0a246 | C178: 115ec4a1efb345dab71ae0bd80d58f39 | D178: van_1
A179: 45873 | B179: cargo_6b1dda59786944109d775dd79079af06 | C179: 591de50eccc54ee284238f494ff60b31 | D179: lcv_m_0
A180: 45873 | B180: cargo_0e9f900bd2d047a7aa4358cfe77c48fe | C180: e38f25ff6686424b9d019733f161f6ee | D180: van_0
A181: 45873 | B181: cargo_1e413250f200414789b6708b5ef887b4 | C181: 134f5be090b846c8894fef73dfd408a9 | D181: lcv_l_0
A182: 45873 | B182: cargo_e4b2f0e254de453a91de903f8e912f21 | C182: e38f25ff6686424b9d019733f161f6ee | D182: van_1
A183: 45873 | B183: 98cc8e12e55a3a5f80006d961e30c304 | C183: 09c6af7919504e23830a67fb114dca8a | D183: lcv_m_0
A184: 45873 | B184: cargo_5664f970ff5f4a49acb445c13572926a | C184: 72eafabaab6b43528bb95de4ed39cfe7 | D184: van_0
... A1803: 45867 | B1803: 1f406fad5c7dd165bac385c7eccf40e2 | C1803: 8970a58b52494b109882dbc683ecf58e | D1803: lcv_m_1

Sheet доставки 22.07
A1: local date | B1: order_id | C1: executor_profile_id | D1: cargo size & loaders
A2: 45866 | B2: cargo_7ea28155255c4d17a6826de8bb0f0bbf | C2: 9b369087045343529f12618729b65518 | D2: lcv_m_X_loaders | S2: Опция
A3: 45866 | B3: 232915e30b7a3fc594429b35641ba039 | C3: 8688d0be56024d0298346d36f05e2a80 | D3: lcv_m_0 | S3: =IF(H3>0,"L1",IF(G3>0,"L0",IF(L3>0,"M2",IF(K3>0,"M1",IF(J3>0,"M0",IF(P3>0,"S2",IF(O3>0,"S1","S0"))))))) -> M0
A4: 45866 | B4: cargo_b06ab9130efc48699b39aaccba709c35 | C4: f8415012583440d8a6fbd302091edf25 | D4: lcv_m_0 | S4: =IF(H4>0,"L1",IF(G4>0,"L0",IF(L4>0,"M2",IF(K4>0,"M1",IF(J4>0,"M0",IF(P4>0,"S2",IF(O4>0,"S1","S0"))))))) -> S0
A5: 45866 | B5: cargo_6878db6d7e844f5782366bececb92780 | C5: 63ed8ccd9c3a4215befe96339cb66c7c | D5: van_0 | S5: =IF(H5>0,"L1",IF(G5>0,"L0",IF(L5>0,"M2",IF(K5>0,"M1",IF(J5>0,"M0",IF(P5>0,"S2",IF(O5>0,"S1","S0"))))))) -> L0
A6: 45866 | B6: cargo_498cd4322f30448e998f7834a58d6b30 | C6: e56bac68fc034ec0be34afd6352f99d4 | D6: lcv_m_0 | S6: =IF(H6>0,"L1",IF(G6>0,"L0",IF(L6>0,"M2",IF(K6>0,"M1",IF(J6>0,"M0",IF(P6>0,"S2",IF(O6>0,"S1","S0"))))))) -> L1
A7: 45866 | B7: cargo_ab98c363d3a84f1697e2023c13d8d199 | C7: 26fa7973a92f4236bf1d7085d5673240 | D7: lcv_l_0 | S7: =IF(H7>0,"L1",IF(G7>0,"L0",IF(L7>0,"M2",IF(K7>0,"M1",IF(J7>0,"M0",IF(P7>0,"S2",IF(O7>0,"S1","S0"))))))) -> S0
A8: 45866 | B8: cargo_4b736931fd6a435795ce34edadd37fd2 | C8: 3230ea2c67a64ad7b82cd545bf681a1c | D8: lcv_m_0 | S8: =IF(H8>0,"L1",IF(G8>0,"L0",IF(L8>0,"M2",IF(K8>0,"M1",IF(J8>0,"M0",IF(P8>0,"S2",IF(O8>0,"S1","S0"))))))) -> L0
A9: 45866 | B9: cargo_ae5c4c977eb64023b518a09992288e2a | C9: 124786ba7f414d6896a26055f91941a6 | D9: van_0 | S9: =IF(H9>0,"L1",IF(G9>0,"L0",IF(L9>0,"M2",IF(K9>0,"M1",IF(J9>0,"M0",IF(P9>0,"S2",IF(O9>0,"S1","S0"))))))) -> S0
A10: 45866 | B10: cargo_fe75029b64a148dfb5760b1189dbbb4d | C10: 51626aa3f8074da9858ebb56753e40dc | D10: van_0 | S10: =IF(H10>0,"L1",IF(G10>0,"L0",IF(L10>0,"M2",IF(K10>0,"M1",IF(J10>0,"M0",IF(P10>0,"S2",IF(O10>0,"S1","S0"))))))) -> S1
A11: 45866 | B11: cargo_cd8fb8b75a2f45399796ae06e32ec18e | C11: 905cbe8acc084fa183abc43b0f4b5076 | D11: lcv_l_1 | S11: =IF(H11>0,"L1",IF(G11>0,"L0",IF(L11>0,"M2",IF(K11>0,"M1",IF(J11>0,"M0",IF(P11>0,"S2",IF(O11>0,"S1","S0"))))))) -> S0
A12: 45866 | B12: cargo_cf6cc64963e44fad9115f4afac9a8168 | C12: 88d9eb9885fa4e01995e413133cd3d1d | D12: lcv_m_0 | S12: =IF(H12>0,"L1",IF(G12>0,"L0",IF(L12>0,"M2",IF(K12>0,"M1",IF(J12>0,"M0",IF(P12>0,"S2",IF(O12>0,"S1","S0"))))))) -> S0
A13: 45866 | B13: cargo_a5dd8f24d0db4d74a9081f22490e0379 | C13: 883155a3c4c84a9d9699ea6cb662b014 | D13: lcv_l_0 | S13: =IF(H13>0,"L1",IF(G13>0,"L0",IF(L13>0,"M2",IF(K13>0,"M1",IF(J13>0,"M0",IF(P13>0,"S2",IF(O13>0,"S1","S0"))))))) -> L0
A14: 45866 | B14: cargo_06fcbb1a22df49cbaedcd5a590b96d9f | C14: 72eafabaab6b43528bb95de4ed39cfe7 | D14: van_1 | S14: =IF(H14>0,"L1",IF(G14>0,"L0",IF(L14>0,"M2",IF(K14>0,"M1",IF(J14>0,"M0",IF(P14>0,"S2",IF(O14>0,"S1","S0"))))))) -> M0
... A170: 45866 | B170: cargo_7b548312fa204e6db8b4ab3408f9fd3a | C170: b5badc10e6e345f7afeaf270d1d971ae | D170: lcv_m_0 | S170: =IF(H170>0,"L1",IF(G170>0,"L0",IF(L170>0,"M2",IF(K170>0,"M1",IF(J170>0,"M0",IF(P170>0,"S2",IF(O170>0,"S1","S0"))))))) -> L1
A171: 45866 | B171: cargo_570c26d16af7486d845b4e401bc6ad68 | C171: 7a9088ba1c584c2d8b695c9bdffdf2f3 | D171: van_0
A172: 45866 | B172: cargo_a9055d2368914e678338cec7432fab2d | C172: f844ec8249544474bab6e405172651f5 | D172: lcv_l_0
A173: 45866 | B173: cargo_9e60f6a781734c18b10e255a48a3dbbd | C173: 124786ba7f414d6896a26055f91941a6 | D173: van_0
A174: 45866 | B174: cargo_54a7a76c6efd432dae1b205099f192ed | C174: 124786ba7f414d6896a26055f91941a6 | D174: van_0
A175: 45866 | B175: cargo_abdd42fff1e54c9d87a8eef1f0f25221 | C175: 124786ba7f414d6896a26055f91941a6 | D175: van_0
A176: 45866 | B176: cargo_7b81e4ab423148a5ac4f9536329face9 | C176: 34aa1bc97f5a4f3398facbd2a23b4f2e | D176: lcv_m_0
A177: 45866 | B177: cargo_821c268379e943569722abc23e072d77 | C177: 63ed8ccd9c3a4215befe96339cb66c7c | D177: van_0
A178: 45866 | B178: cargo_0d4ea3929ba34765a242376d091aac64 | C178: c6a2c4a6a16eaab8f17c68c475ab723f | D178: van_0
A179: 45866 | B179: cargo_71a7ee3f2a3e49f3a86f203ed40f1a1b | C179: 4838f63fd4cb42789463e2f7fa84bb9b | D179: van_0
A180: 45866 | B180: cargo_484715f6f6ee41f5b20d9b75d648b5ce | C180: e6556175182544e7b7d8a00276bd4d6a | D180: lcv_l_0
A181: 45866 | B181: f13692f8654ab3798e1bb70ebde87b85 | C181: 95263b54a2f44647ba31046ce9070c75 | D181: lcv_m_0
A182: 45866 | B182: cargo_0d4ea3929ba34765a242376d091aac64 | C182: c6a2c4a6a16eaab8f17c68c475ab723f | D182: van_0
... A1788: 45860 | B1788: b60c5af635552e0a960dabd32e692418 | C1788: 68c2d5a61253443193de36490fd562e5 | D1788: van_0

Sheet доставки 15.07
A1: local date | B1: order_id | C1: executor_profile_id | D1: cargo size & loaders
A2: 45859 | B2: 7bb0c20a3cf5df37a3f131a83ce2a98f | C2: 5e3ba49580d345adbfea9bbb7e028c81 | D2: lcv_m_0 | S2: Опция
A3: 45859 | B3: cargo_c8903b0dc676408693797cda3a243588 | C3: b5badc10e6e345f7afeaf270d1d971ae | D3: lcv_m_0 | S3: =IF(H3>0,"L1",IF(G3>0,"L0",IF(L3>0,"M2",IF(K3>0,"M1",IF(J3>0,"M0",IF(P3>0,"S2",IF(O3>0,"S1","S0"))))))) -> L0
A4: 45859 | B4: cargo_b782439638504ebc8bc27fe87b51d68f | C4: 57df775d2839499f96a53ae23a712801 | D4: lcv_m_0 | S4: =IF(H4>0,"L1",IF(G4>0,"L0",IF(L4>0,"M2",IF(K4>0,"M1",IF(J4>0,"M0",IF(P4>0,"S2",IF(O4>0,"S1","S0"))))))) -> M0
A5: 45859 | B5: cargo_ddfd9a0f5708424f9b0561fa0f733139 | C5: a40d4ff06d294ebdbf79f4211a1f99b0 | D5: van_0 | S5: =IF(H5>0,"L1",IF(G5>0,"L0",IF(L5>0,"M2",IF(K5>0,"M1",IF(J5>0,"M0",IF(P5>0,"S2",IF(O5>0,"S1","S0"))))))) -> M0
A6: 45859 | B6: cargo_7358771729694cb7935eb998a65a2a5d | C6: f844ec8249544474bab6e405172651f5 | D6: lcv_l_1 | S6: =IF(H6>0,"L1",IF(G6>0,"L0",IF(L6>0,"M2",IF(K6>0,"M1",IF(J6>0,"M0",IF(P6>0,"S2",IF(O6>0,"S1","S0"))))))) -> M0
A7: 45859 | B7: cargo_e698ff128ef24474ad535c9debd74a7e | C7: 2d8d71fefdcc497e99e110ff65e659cf | D7: van_0 | S7: =IF(H7>0,"L1",IF(G7>0,"L0",IF(L7>0,"M2",IF(K7>0,"M1",IF(J7>0,"M0",IF(P7>0,"S2",IF(O7>0,"S1","S0"))))))) -> L1
A8: 45859 | B8: cargo_415e96f432624ab78df2c64119154b5b | C8: f8415012583440d8a6fbd302091edf25 | D8: van_0 | S8: =IF(H8>0,"L1",IF(G8>0,"L0",IF(L8>0,"M2",IF(K8>0,"M1",IF(J8>0,"M0",IF(P8>0,"S2",IF(O8>0,"S1","S0"))))))) -> S0
A9: 45859 | B9: 6afeb06196fb21098045632507d7ad63 | C9: 5e3ba49580d345adbfea9bbb7e028c81 | D9: lcv_m_0 | S9: =IF(H9>0,"L1",IF(G9>0,"L0",IF(L9>0,"M2",IF(K9>0,"M1",IF(J9>0,"M0",IF(P9>0,"S2",IF(O9>0,"S1","S0"))))))) -> S0
A10: 45859 | B10: cargo_47dca21efb6d4dccbcc1176da42ec1a6 | C10: f58af0dc9a2c4e71a37ffed0e5a3da63 | D10: lcv_m_2 | S10: =IF(H10>0,"L1",IF(G10>0,"L0",IF(L10>0,"M2",IF(K10>0,"M1",IF(J10>0,"M0",IF(P10>0,"S2",IF(O10>0,"S1","S0"))))))) -> S1
A11: 45859 | B11: cargo_e9f42e7e5c5a445586a80d3b430e5127 | C11: 6b84cc9c28144b84b21ade7ae4d5c4fe | D11: lcv_m_0 | S11: =IF(H11>0,"L1",IF(G11>0,"L0",IF(L11>0,"M2",IF(K11>0,"M1",IF(J11>0,"M0",IF(P11>0,"S2",IF(O11>0,"S1","S0"))))))) -> S0
A12: 45859 | B12: cargo_634d8c4ca8b24abb9b69cb6a1b741cd9 | C12: 51626aa3f8074da9858ebb56753e40dc | D12: van_0 | S12: =IF(H12>0,"L1",IF(G12>0,"L0",IF(L12>0,"M2",IF(K12>0,"M1",IF(J12>0,"M0",IF(P12>0,"S2",IF(O12>0,"S1","S0"))))))) -> L0
A13: 45859 | B13: cargo_2a4a703882a34715867a81d53fb240d1 | C13: c8a91160c4a4423c982b123935469ed8 | D13: van_0 | S13: =IF(H13>0,"L1",IF(G13>0,"L0",IF(L13>0,"M2",IF(K13>0,"M1",IF(J13>0,"M0",IF(P13>0,"S2",IF(O13>0,"S1","S0"))))))) -> L0
A14: 45859 | B14: cargo_43e5044e7a6d4f0aa244d922cca54b7c | C14: 0c5ffa06e1cc4f09a46bac4aae1eae37 | D14: van_0 | S14: =IF(H14>0,"L1",IF(G14>0,"L0",IF(L14>0,"M2",IF(K14>0,"M1",IF(J14>0,"M0",IF(P14>0,"S2",IF(O14>0,"S1","S0"))))))) -> M0
... A174: 45859 | B174: cargo_d4784a531bcf410792fbb0162d99dab8 | C174: a5aaecdea39f4677917161cc50e1b934 | D174: lcv_l_1 | S174: =IF(H174>0,"L1",IF(G174>0,"L0",IF(L174>0,"M2",IF(K174>0,"M1",IF(J174>0,"M0",IF(P174>0,"S2",IF(O174>0,"S1","S0"))))))) -> L1
A175: 45859 | B175: cargo_09a025a3b98746988fa25e0c15e29763 | C175: 1c14275c16404711a2ef1c87a2412a8e | D175: lcv_m_0
A176: 45859 | B176: cargo_5f205116ce77409dab621fb45a7db062 | C176: 77f4c24e9ddd46798d9f1fa92b2101bf | D176: lcv_m_0
A177: 45859 | B177: cargo_ba79fb499d1d44eca4d3db4e6f6139e5 | C177: b0e85d03fc3545c5af0d3cb495f280a8 | D177: lcv_m_0
A178: 45859 | B178: cargo_a25ca0366b7c49a3b4b501f5be67d271 | C178: 43d9e8e49cd44ae3873c6619ed542843 | D178: lcv_m_1
A179: 45859 | B179: cargo_520da4f4700e452ea3373a13db3939ee | C179: e6556175182544e7b7d8a00276bd4d6a | D179: lcv_l_0
A180: 45859 | B180: cargo_ecda0349e88a4d0e850aaad74f2b2085 | C180: c6a2c4a6a16eaab8f17c68c475ab723f | D180: van_1
A181: 45859 | B181: ffbd890c863287b8bf9721156ccedde6 | C181: bf3ca565071043328efccdde0c445bae | D181: van_1
A182: 45859 | B182: cargo_0087a4938f1b48c58f955d6208f27c3d | C182: 3f90112bc6864c988db4cad3f2c5d00a | D182: van_2
A183: 45859 | B183: cargo_d8c1d11873e94f6a95ffb3271cd87796 | C183: 3f90112bc6864c988db4cad3f2c5d00a | D183: van_2
A184: 45859 | B184: bffe25a6140135ee96b132a568f306db | C184: 78552ba7ced94f0f9ea224b5f7dae570 | D184: van_1
A185: 45859 | B185: cargo_79dd6b1273db455cb9616f5f06cd2a45 | C185: ae72d5fff7de4e9caeb2b60cbdfcfe53 | D185: van_0
A186: 45859 | B186: cargo_71b8bd54cb3f42dcaed55203eba383f9 | C186: a3d9bb049d834b428027af01f4efcc02 | D186: van_0
... A1877: 45853 | B1877: cargo_054a5a05638243aaa026c2b4504d15c5 | C1877: 5298ec91efe6405aa7350d7c2d98a022 | D1877: van_1

Sheet доставки 08.07
A1: local date | B1: order_id | C1: executor_profile_id | D1: cargo size & loaders
A2: 45852 | B2: cargo_7d1960a8ef2141dc8bd05c911d8d37fb | C2: f844ec8249544474bab6e405172651f5 | D2: lcv_m_0 | S2: Опция
A3: 45852 | B3: cargo_3d90fe0d729f437794ab0ed30a978893 | C3: ae72d5fff7de4e9caeb2b60cbdfcfe53 | D3: van_0 | S3: =IF(H3>0,"L1",IF(G3>0,"L0",IF(L3>0,"M2",IF(K3>0,"M1",IF(J3>0,"M0",IF(P3>0,"S2",IF(O3>0,"S1","S0"))))))) -> L0
A4: 45852 | B4: cargo_246ab47071a24431825dcd429c93fa26 | C4: c6a2c4a6a16eaab8f17c68c475ab723f | D4: van_1 | S4: =IF(H4>0,"L1",IF(G4>0,"L0",IF(L4>0,"M2",IF(K4>0,"M1",IF(J4>0,"M0",IF(P4>0,"S2",IF(O4>0,"S1","S0"))))))) -> L1
A5: 45852 | B5: cargo_246ab47071a24431825dcd429c93fa26 | C5: c6a2c4a6a16eaab8f17c68c475ab723f | D5: van_1 | S5: =IF(H5>0,"L1",IF(G5>0,"L0",IF(L5>0,"M2",IF(K5>0,"M1",IF(J5>0,"M0",IF(P5>0,"S2",IF(O5>0,"S1","S0"))))))) -> S0
A6: 45852 | B6: 2bd04bf11117da9f830c2af6844b490d | C6: 78552ba7ced94f0f9ea224b5f7dae570 | D6: van_1 | S6: =IF(H6>0,"L1",IF(G6>0,"L0",IF(L6>0,"M2",IF(K6>0,"M1",IF(J6>0,"M0",IF(P6>0,"S2",IF(O6>0,"S1","S0"))))))) -> M0
A7: 45852 | B7: 2bd04bf11117da9f830c2af6844b490d | C7: 78552ba7ced94f0f9ea224b5f7dae570 | D7: van_1 | S7: =IF(H7>0,"L1",IF(G7>0,"L0",IF(L7>0,"M2",IF(K7>0,"M1",IF(J7>0,"M0",IF(P7>0,"S2",IF(O7>0,"S1","S0"))))))) -> S0
A8: 45852 | B8: 2bd04bf11117da9f830c2af6844b490d | C8: 78552ba7ced94f0f9ea224b5f7dae570 | D8: van_1 | S8: =IF(H8>0,"L1",IF(G8>0,"L0",IF(L8>0,"M2",IF(K8>0,"M1",IF(J8>0,"M0",IF(P8>0,"S2",IF(O8>0,"S1","S0"))))))) -> M2
A9: 45852 | B9: cargo_8513b03c43f24ea49258ea221199a85d | C9: f58af0dc9a2c4e71a37ffed0e5a3da63 | D9: lcv_m_0 | S9: =IF(H9>0,"L1",IF(G9>0,"L0",IF(L9>0,"M2",IF(K9>0,"M1",IF(J9>0,"M0",IF(P9>0,"S2",IF(O9>0,"S1","S0"))))))) -> S1
A10: 45852 | B10: cargo_c89a5e73bf5c44c98c63bb010040d1e8 | C10: a1e84c6d8cd941f6b06487dadc8e0008 | D10: lcv_m_0 | S10: =IF(H10>0,"L1",IF(G10>0,"L0",IF(L10>0,"M2",IF(K10>0,"M1",IF(J10>0,"M0",IF(P10>0,"S2",IF(O10>0,"S1","S0"))))))) -> M0
A11: 45852 | B11: 0e465fd3d66a33689cadaad144fee3dd | C11: 14da81d9b71b4556d54cb20f7b3f1cf4 | D11: lcv_m_0 | S11: =IF(H11>0,"L1",IF(G11>0,"L0",IF(L11>0,"M2",IF(K11>0,"M1",IF(J11>0,"M0",IF(P11>0,"S2",IF(O11>0,"S1","S0"))))))) -> S1
A12: 45852 | B12: cargo_bf7db481efcc49ba870a8ec3724568ad | C12: f15c33c98f5d48fb89ae0c7c5e257dba | D12: lcv_l_0 | S12: =IF(H12>0,"L1",IF(G12>0,"L0",IF(L12>0,"M2",IF(K12>0,"M1",IF(J12>0,"M0",IF(P12>0,"S2",IF(O12>0,"S1","S0"))))))) -> S0
A13: 45852 | B13: cargo_88cfc3256a4b4c97956b711f4dda88a2 | C13: ee2e5e5eeaee46c88a0c05805d330415 | D13: lcv_m_0 | S13: =IF(H13>0,"L1",IF(G13>0,"L0",IF(L13>0,"M2",IF(K13>0,"M1",IF(J13>0,"M0",IF(P13>0,"S2",IF(O13>0,"S1","S0"))))))) -> M0
A14: 45852 | B14: cargo_cb981afaaeeb44df947b780fc040c61e | C14: b1a58f50e8044baf8bab550369918b37 | D14: van_0 | S14: =IF(H14>0,"L1",IF(G14>0,"L0",IF(L14>0,"M2",IF(K14>0,"M1",IF(J14>0,"M0",IF(P14>0,"S2",IF(O14>0,"S1","S0"))))))) -> L0
... A166: 45852 | B166: 2bd04bf11117da9f830c2af6844b490d | C166: 78552ba7ced94f0f9ea224b5f7dae570 | D166: van_1 | S166: =IF(H166>0,"L1",IF(G166>0,"L0",IF(L166>0,"M2",IF(K166>0,"M1",IF(J166>0,"M0",IF(P166>0,"S2",IF(O166>0,"S1","S0"))))))) -> L1
A167: 45852 | B167: cargo_246ab47071a24431825dcd429c93fa26 | C167: c6a2c4a6a16eaab8f17c68c475ab723f | D167: van_1
A168: 45852 | B168: cargo_246ab47071a24431825dcd429c93fa26 | C168: c6a2c4a6a16eaab8f17c68c475ab723f | D168: van_1
A169: 45852 | B169: 2bd04bf11117da9f830c2af6844b490d | C169: 78552ba7ced94f0f9ea224b5f7dae570 | D169: van_1
A170: 45852 | B170: 2bd04bf11117da9f830c2af6844b490d | C170: 78552ba7ced94f0f9ea224b5f7dae570 | D170: van_1
A171: 45852 | B171: cargo_2b5a27d8a8d446f2866f4df06640983d | C171: 3eae87f9e9fe41c7a631d940fd5c9196 | D171: lcv_m_2
A172: 45852 | B172: 5192d3f1deb2c11db1a924800bc287bd | C172: 5e3ba49580d345adbfea9bbb7e028c81 | D172: lcv_m_0
A173: 45852 | B173: cargo_07fac856ac904ac0867a3b5cee3637ec | C173: 134f5be090b846c8894fef73dfd408a9 | D173: lcv_l_0
A174: 45852 | B174: cargo_0b9b15e86b664c35a01c50a44d7734d8 | C174: 164b7bd8f6a14a48896067769cb9b217 | D174: lcv_m_0
A175: 45852 | B175: 4ffb189cf33732cf8dfef50df651b5ea | C175: 09bbfa6c6a524586a7367281e1d46ef2 | D175: van_0
A176: 45852 | B176: cargo_8f9c6931819740d5914c1ddd1a86859c | C176: 22a62dd656c2dc2532f2d8391832d0a8 | D176: lcv_l_0
A177: 45852 | B177: cargo_73790f4962414af8a4140dd791113ab9 | C177: 3f90112bc6864c988db4cad3f2c5d00a | D177: van_1
A178: 45852 | B178: cargo_ce8ef8a1f4e045d9ba510a9bc0d72c4f | C178: c8ba14f4ad00c92143a75c9d89a2199d | D178: lcv_m_0
... A1949: 45846 | B1949: 5eac7bb3f11b88a782cf976736de6cb4 | C1949: 1ffca3c095d141d2aae14304b878e552 | D1949: lcv_m_0

Sheet доставки 01.07
A1: local date | B1: order_id | C1: executor_profile_id | D1: cargo size & loaders | X1: https://datalens.yandex-team.ru/am8u3uq2e7ow2-cancels-corporate-clients-c2c?tab=vd&state=c4aa8ad52652
A2: 45845 | B2: cargo_8c7b68db2dc6433594e6c16b77ab8fc6 | C2: fcc5a173a9c84f7787bdf3285acc529c | D2: lcv_m_0 | S2: Опция
A3: 45845 | B3: cargo_ef28cf610de34b768059fc09edc03dfc | C3: c8ba14f4ad00c92143a75c9d89a2199d | D3: lcv_m_0 | S3: =IF(H3>0,"L1",IF(G3>0,"L0",IF(L3>0,"M2",IF(K3>0,"M1",IF(J3>0,"M0",IF(P3>0,"S2",IF(O3>0,"S1","S0"))))))) -> S0
A4: 45845 | B4: 8bd9b62e60053e5a882f6fb83ed97b5e | C4: 7b46c524b2a14194bdec93b67f815440 | D4: van_0 | S4: =IF(H4>0,"L1",IF(G4>0,"L0",IF(L4>0,"M2",IF(K4>0,"M1",IF(J4>0,"M0",IF(P4>0,"S2",IF(O4>0,"S1","S0"))))))) -> L0
A5: 45845 | B5: cargo_a7ee0bd390984019b8943ca66d78eabb | C5: 0c5ffa06e1cc4f09a46bac4aae1eae37 | D5: van_0 | S5: =IF(H5>0,"L1",IF(G5>0,"L0",IF(L5>0,"M2",IF(K5>0,"M1",IF(J5>0,"M0",IF(P5>0,"S2",IF(O5>0,"S1","S0"))))))) -> M0
A6: 45845 | B6: 314c1b6d2f95d5edbb49695882c7f0b4 | C6: 14da81d9b71b4556d54cb20f7b3f1cf4 | D6: lcv_m_0 | S6: =IF(H6>0,"L1",IF(G6>0,"L0",IF(L6>0,"M2",IF(K6>0,"M1",IF(J6>0,"M0",IF(P6>0,"S2",IF(O6>0,"S1","S0"))))))) -> M1
A7: 45845 | B7: cargo_fb2e6d3d7b4d4134b53beefb417b64c5 | C7: 22647c4704494334a95bdb62e46d3000 | D7: lcv_m_0 | S7: =IF(H7>0,"L1",IF(G7>0,"L0",IF(L7>0,"M2",IF(K7>0,"M1",IF(J7>0,"M0",IF(P7>0,"S2",IF(O7>0,"S1","S0"))))))) -> M0
A8: 45845 | B8: cargo_c7945ddea9824c518e4fc09f02cb3374 | C8: c8a91160c4a4423c982b123935469ed8 | D8: van_0 | S8: =IF(H8>0,"L1",IF(G8>0,"L0",IF(L8>0,"M2",IF(K8>0,"M1",IF(J8>0,"M0",IF(P8>0,"S2",IF(O8>0,"S1","S0"))))))) -> S0
A9: 45845 | B9: cargo_f941f868bec240d190f06933da5b649c | C9: f844ec8249544474bab6e405172651f5 | D9: lcv_m_0 | S9: =IF(H9>0,"L1",IF(G9>0,"L0",IF(L9>0,"M2",IF(K9>0,"M1",IF(J9>0,"M0",IF(P9>0,"S2",IF(O9>0,"S1","S0"))))))) -> M2
A10: 45845 | B10: cargo_3903526595e548adbbd912c93193bad3 | C10: 4ccb42012fc64a2c8718f1fdadc87dbf | D10: van_0 | S10: =IF(H10>0,"L1",IF(G10>0,"L0",IF(L10>0,"M2",IF(K10>0,"M1",IF(J10>0,"M0",IF(P10>0,"S2",IF(O10>0,"S1","S0"))))))) -> S1
A11: 45845 | B11: cargo_16b0c7528b254a03b1b4571bccbf044b | C11: 68bb1fbc28874515b67bf29c3ecaa465 | D11: van_0 | S11: =IF(H11>0,"L1",IF(G11>0,"L0",IF(L11>0,"M2",IF(K11>0,"M1",IF(J11>0,"M0",IF(P11>0,"S2",IF(O11>0,"S1","S0"))))))) -> M2
A12: 45845 | B12: cargo_05e2d629ad0b491eb3dfd0c3556f19af | C12: b1a58f50e8044baf8bab550369918b37 | D12: lcv_m_0 | S12: =IF(H12>0,"L1",IF(G12>0,"L0",IF(L12>0,"M2",IF(K12>0,"M1",IF(J12>0,"M0",IF(P12>0,"S2",IF(O12>0,"S1","S0"))))))) -> S1
A13: 45845 | B13: cargo_1fb9f45b3da3478298ec435fa9e9cebd | C13: 548f238344874a97bede58cb74f36f48 | D13: van_0 | S13: =IF(H13>0,"L1",IF(G13>0,"L0",IF(L13>0,"M2",IF(K13>0,"M1",IF(J13>0,"M0",IF(P13>0,"S2",IF(O13>0,"S1","S0"))))))) -> S0
A14: 45845 | B14: cargo_6497b2aea8664145843f8e5f35871333 | C14: c8ba14f4ad00c92143a75c9d89a2199d | D14: lcv_m_0 | S14: =IF(H14>0,"L1",IF(G14>0,"L0",IF(L14>0,"M2",IF(K14>0,"M1",IF(J14>0,"M0",IF(P14>0,"S2",IF(O14>0,"S1","S0"))))))) -> S1
... A173: 45845 | B173: cargo_55d2f331c2274376a627789c7a5f39db | C173: 77f4c24e9ddd46798d9f1fa92b2101bf | D173: lcv_l_0 | S173: =IF(H173>0,"L1",IF(G173>0,"L0",IF(L173>0,"M2",IF(K173>0,"M1",IF(J173>0,"M0",IF(P173>0,"S2",IF(O173>0,"S1","S0"))))))) -> L1
A174: 45845 | B174: cargo_3193e6eb14eb490e9da4a408eba6f975 | C174: 905887ce171f42ffac422bffab4dbef1 | D174: lcv_m_0
A175: 45845 | B175: cargo_33074f0f886c42fca34781bcde13e4cd | C175: 77f4c24e9ddd46798d9f1fa92b2101bf | D175: lcv_m_0
A176: 45845 | B176: 0be43794ddbfee1bada82f1c14de79dc | C176: 14da81d9b71b4556d54cb20f7b3f1cf4 | D176: lcv_m_0
A177: 45845 | B177: cargo_4abf07e69314437ebbda55909d4a001c | C177: 66feb8d7c1f94fd191fa21e550721fac | D177: lcv_m_0
A178: 45845 | B178: cargo_0fdd0d18a21345778809a0c9b570a10c | C178: 2f05cf9c16a2f2fc69a59a8d3a281676 | D178: lcv_l_X_loaders
A179: 45845 | B179: cargo_a273e67fd9e04660b15d74fea6535bba | C179: 5399111a09804d7f8c66d2daf2aa6f88 | D179: van_X_loaders
A180: 45845 | B180: cargo_5741d08a31c34e9db67392374afefb17 | C180: 66feb8d7c1f94fd191fa21e550721fac | D180: lcv_m_0
A181: 45845 | B181: cargo_d61ca373dea54bd3bea7d852d0e68e4e | C181: b0e85d03fc3545c5af0d3cb495f280a8 | D181: lcv_m_0
A182: 45845 | B182: cargo_984ac51ed869412d99de8cbc1c8dc1f3 | C182: 905887ce171f42ffac422bffab4dbef1 | D182: lcv_m_0
A183: 45845 | B183: cargo_9b9f8c944d63497b9a5a5abbde171394 | C183: d4e4b073086d4ba7a9eff66e3bd59f4e | D183: van_0
A184: 45845 | B184: cargo_be32203a584c4642b0f2037c25e10cbc | C184: 124786ba7f414d6896a26055f91941a6 | D184: van_0
A185: 45845 | B185: cargo_740d6a253f37431ca1cb792f670ff5df | C185: 5298ec91efe6405aa7350d7c2d98a022 | D185: van_0
... A1920: 45839 | B1920: 43ed101e5364ea4992b6b8069765ec14 | C1920: cb44023279784a49bf068c7acf9974f4 | D1920: van_1

Sheet доставки 24.06
A1: local date | B1: order_id | C1: executor_profile_id | D1: cargo size & loaders | X1: https://datalens.yandex-team.ru/am8u3uq2e7ow2-cancels-corporate-clients-c2c?tab=vd&state=e897715c2652
A2: 45838 | B2: b573d17440b5d7519d03c58399aa5b89 | C2: 76c35d532eaf450f915f88f5266a5f84 | D2: van_1 | S2: Опция
A3: 45838 | B3: b573d17440b5d7519d03c58399aa5b89 | C3: 76c35d532eaf450f915f88f5266a5f84 | D3: van_1 | S3: =IF(H3>0,"L1",IF(G3>0,"L0",IF(L3>0,"M2",IF(K3>0,"M1",IF(J3>0,"M0",IF(P3>0,"S2",IF(O3>0,"S1","S0"))))))) -> L0
A4: 45838 | B4: c416ed5abfc01ec2ae8b19b0aaece2e9 | C4: 2490b863722945409edb37bd7af6650d | D4: van_0 | S4: =IF(H4>0,"L1",IF(G4>0,"L0",IF(L4>0,"M2",IF(K4>0,"M1",IF(J4>0,"M0",IF(P4>0,"S2",IF(O4>0,"S1","S0"))))))) -> M0
A5: 45838 | B5: cargo_789dfff9931745cd8707681e18050aa4 | C5: 44201b88f0d3423b9d3a1f307454a73a | D5: lcv_m_2 | S5: =IF(H5>0,"L1",IF(G5>0,"L0",IF(L5>0,"M2",IF(K5>0,"M1",IF(J5>0,"M0",IF(P5>0,"S2",IF(O5>0,"S1","S0"))))))) -> M0
A6: 45838 | B6: c7fa74bee5fbb092b012fbaa521f7834 | C6: 2c47ce024bae4ad398248506dc00f9a2 | D6: lcv_l_0 | S6: =IF(H6>0,"L1",IF(G6>0,"L0",IF(L6>0,"M2",IF(K6>0,"M1",IF(J6>0,"M0",IF(P6>0,"S2",IF(O6>0,"S1","S0"))))))) -> S0
A7: 45838 | B7: cargo_ce47103f4db34d889583e6b4b36dd67b | C7: ae9f78b05c01424a8f4d732573ec06be | D7: lcv_m_0 | S7: =IF(H7>0,"L1",IF(G7>0,"L0",IF(L7>0,"M2",IF(K7>0,"M1",IF(J7>0,"M0",IF(P7>0,"S2",IF(O7>0,"S1","S0"))))))) -> S0
A8: 45838 | B8: cargo_68bcfe51a4d147c08a90e76f8113f99b | C8: ccdffeab908047c5b8408e5895cace84 | D8: van_0 | S8: =IF(H8>0,"L1",IF(G8>0,"L0",IF(L8>0,"M2",IF(K8>0,"M1",IF(J8>0,"M0",IF(P8>0,"S2",IF(O8>0,"S1","S0"))))))) -> M2
A9: 45838 | B9: cargo_38b2de417c2544f98a71ba2ccb3c9c13 | C9: 50cd883af44342e28553ca78782d3374 | D9: lcv_l_0 | S9: =IF(H9>0,"L1",IF(G9>0,"L0",IF(L9>0,"M2",IF(K9>0,"M1",IF(J9>0,"M0",IF(P9>0,"S2",IF(O9>0,"S1","S0"))))))) -> S1
A10: 45838 | B10: cargo_5c27cb2a3d4a46aabfd0e3d87bee0547 | C10: e3fb70db6f8a455bb8660107ac6ea33b | D10: lcv_m_0 | S10: =IF(H10>0,"L1",IF(G10>0,"L0",IF(L10>0,"M2",IF(K10>0,"M1",IF(J10>0,"M0",IF(P10>0,"S2",IF(O10>0,"S1","S0"))))))) -> M2
A11: 45838 | B11: cargo_51e3f67bc1ae4f0bb614649716cf7082 | C11: 77f4c24e9ddd46798d9f1fa92b2101bf | D11: lcv_l_0 | S11: =IF(H11>0,"L1",IF(G11>0,"L0",IF(L11>0,"M2",IF(K11>0,"M1",IF(J11>0,"M0",IF(P11>0,"S2",IF(O11>0,"S1","S0"))))))) -> S1
A12: 45838 | B12: 04dff72681ba31f8bb3f299c461ff127 | C12: cb44023279784a49bf068c7acf9974f4 | D12: van_0 | S12: =IF(H12>0,"L1",IF(G12>0,"L0",IF(L12>0,"M2",IF(K12>0,"M1",IF(J12>0,"M0",IF(P12>0,"S2",IF(O12>0,"S1","S0"))))))) -> M0
A13: 45838 | B13: cargo_da6da761143b4563b2c8d60ed28a2a5b | C13: 0c5ffa06e1cc4f09a46bac4aae1eae37 | D13: van_1 | S13: =IF(H13>0,"L1",IF(G13>0,"L0",IF(L13>0,"M2",IF(K13>0,"M1",IF(J13>0,"M0",IF(P13>0,"S2",IF(O13>0,"S1","S0"))))))) -> S1
A14: 45838 | B14: cargo_58da42b0fee6467b9fb7ab317369ea7a | C14: 2f05cf9c16a2f2fc69a59a8d3a281676 | D14: lcv_m_0 | S14: =IF(H14>0,"L1",IF(G14>0,"L0",IF(L14>0,"M2",IF(K14>0,"M1",IF(J14>0,"M0",IF(P14>0,"S2",IF(O14>0,"S1","S0"))))))) -> S0
... A184: 45838 | B184: cargo_f22cc037b1564032bb4864d9caf15c4b | C184: 3e5fec28a9044189b707a7ef40ec993c | D184: van_0 | S184: =IF(H184>0,"L1",IF(G184>0,"L0",IF(L184>0,"M2",IF(K184>0,"M1",IF(J184>0,"M0",IF(P184>0,"S2",IF(O184>0,"S1","S0"))))))) -> L1
A185: 45838 | B185: 192393ac2aed3e518d5ba6df0b2c7002 | C185: 2490b863722945409edb37bd7af6650d | D185: van_0
A186: 45838 | B186: 60216c1f63d2c071badee18333b343a9 | C186: 015faaa95062441487fc9fa2325e684f | D186: lcv_l_0
A187: 45838 | B187: cargo_e261e6c69bf14da3bb2d7586cdf777e4 | C187: 4ccb42012fc64a2c8718f1fdadc87dbf | D187: van_0
A188: 45838 | B188: 712aa60780e530ffb8a938ee8b287431 | C188: 14da81d9b71b4556d54cb20f7b3f1cf4 | D188: lcv_m_0
A189: 45838 | B189: cargo_dbaccbd2c75f4bb6a1d207a93d8ffa06 | C189: fcc5a173a9c84f7787bdf3285acc529c | D189: lcv_m_0
A190: 45838 | B190: cargo_acafb422c5574009a6fdd97a057c876d | C190: f844ec8249544474bab6e405172651f5 | D190: lcv_l_0
A191: 45838 | B191: cargo_64753a66af69458ebf01eb459279ec19 | C191: 66feb8d7c1f94fd191fa21e550721fac | D191: lcv_m_0
A192: 45838 | B192: cargo_8e1ae4637716435d9e4afb7440569fd9 | C192: 3f90112bc6864c988db4cad3f2c5d00a | D192: van_0
A193: 45838 | B193: 0e79703c4938d402904b8b2f8da8562e | C193: 11136c1991824ab88d3c4baf9ac853fb | D193: lcv_m_0
A194: 45838 | B194: cargo_c174c03965a64fd3ac0b4608822622d7 | C194: e98cb9b091334ea3aef54f5770c89903 | D194: lcv_m_0
A195: 45838 | B195: cargo_d4eccdf9901d4c98989f3164d3677d53 | C195: ccdffeab908047c5b8408e5895cace84 | D195: van_1
A196: 45838 | B196: b573d17440b5d7519d03c58399aa5b89 | C196: 76c35d532eaf450f915f88f5266a5f84 | D196: van_1
... A1795: 45832 | B1795: cargo_ed098e5496d74480b3db24531c3f3240 | C1795: 2d196adb18c5459f8e8ba27300368da2 | D1795: lcv_m_X_loaders

Sheet доставки 17.06
A1: local date | B1: order_id | C1: executor_profile_id | D1: cargo size & loaders | X1: https://datalens.yandex-team.ru/am8u3uq2e7ow2-cancels-corporate-clients-c2c?tab=vd&state=822af7ca2652
A2: 45831 | B2: cargo_e4bc83eb7f0548cfb5a316bca2e33fbb | C2: dbaf1ac630394a44a9a1002c79b0357e | D2: lcv_m_0 | S2: Опция
A3: 45831 | B3: aede8263c357b652b2f3767d9bf56511 | C3: a96331e43b3244dbb9b61a361de136a7 | D3: lcv_m_0 | S3: =IF(H3>0,"L1",IF(G3>0,"L0",IF(L3>0,"M2",IF(K3>0,"M1",IF(J3>0,"M0",IF(P3>0,"S2",IF(O3>0,"S1","S0"))))))) -> L0
A4: 45831 | B4: cargo_ad0e858f46264f2c9e9c7aed8f75c833 | C4: c8ba14f4ad00c92143a75c9d89a2199d | D4: lcv_m_0 | S4: =IF(H4>0,"L1",IF(G4>0,"L0",IF(L4>0,"M2",IF(K4>0,"M1",IF(J4>0,"M0",IF(P4>0,"S2",IF(O4>0,"S1","S0"))))))) -> M1
A5: 45831 | B5: cargo_85daaa172dc44192bdd46b023c0917f1 | C5: fcc5a173a9c84f7787bdf3285acc529c | D5: lcv_m_0 | S5: =IF(H5>0,"L1",IF(G5>0,"L0",IF(L5>0,"M2",IF(K5>0,"M1",IF(J5>0,"M0",IF(P5>0,"S2",IF(O5>0,"S1","S0"))))))) -> L1
A6: 45831 | B6: cargo_7053a2227bf04bd2947d5284d741f0e9 | C6: f844ec8249544474bab6e405172651f5 | D6: lcv_l_0 | S6: =IF(H6>0,"L1",IF(G6>0,"L0",IF(L6>0,"M2",IF(K6>0,"M1",IF(J6>0,"M0",IF(P6>0,"S2",IF(O6>0,"S1","S0"))))))) -> M0
A7: 45831 | B7: cargo_11300864f5c84affa2e1806da20c076b | C7: bf825b978b174f61bd874bee7737cbe4 | D7: van_0 | S7: =IF(H7>0,"L1",IF(G7>0,"L0",IF(L7>0,"M2",IF(K7>0,"M1",IF(J7>0,"M0",IF(P7>0,"S2",IF(O7>0,"S1","S0"))))))) -> M0
A8: 45831 | B8: cargo_558dd47eb8c74c208b6dbf7fddaa4688 | C8: 905887ce171f42ffac422bffab4dbef1 | D8: lcv_m_0 | S8: =IF(H8>0,"L1",IF(G8>0,"L0",IF(L8>0,"M2",IF(K8>0,"M1",IF(J8>0,"M0",IF(P8>0,"S2",IF(O8>0,"S1","S0"))))))) -> S1
A9: 45831 | B9: cargo_6297dc5d6f004b5ab83a5e37089c1156 | C9: 8798a1de20da4e0dbda73e36dc1f6924 | D9: lcv_m_0 | S9: =IF(H9>0,"L1",IF(G9>0,"L0",IF(L9>0,"M2",IF(K9>0,"M1",IF(J9>0,"M0",IF(P9>0,"S2",IF(O9>0,"S1","S0"))))))) -> M2
A10: 45831 | B10: cargo_433836289e474a22b4240176f79bc00c | C10: 884cf41e96304d1eb28b7b546e7d096f | D10: van_1 | S10: =IF(H10>0,"L1",IF(G10>0,"L0",IF(L10>0,"M2",IF(K10>0,"M1",IF(J10>0,"M0",IF(P10>0,"S2",IF(O10>0,"S1","S0"))))))) -> S1
