Workbook

Sheet затраты 14.07
C2: https://datalens.yandex-team.ru/wbenuos6lxv4o-subsidy-details-advanced?tab=8Z&state=d05e49c91134 | D2: неделя с 14.07
B3: Zone | C3: на русском | D3: sub/GMV | E3: dXgY | F3: MFG | G3: MFGgeo | H3: Substotal
B4: ekb | C4: =VLOOKUP(B4,'население 2023'!C:D,2,0) -> Екб | D4: 0.063 | E4: 894180 | F4: 20839 | G4: 0 | H4: 918519
B5: spb | C5: =VLOOKUP(B5,'население 2023'!C:D,2,0) -> СПб | D5: 0.011 | E5: 648907 | F5: 5839 | G5: 0 | H5: 658746
B6: novosibirsk | C6: =VLOOKUP(B6,'население 2023'!C:D,2,0) -> Нск | D6: 0.037 | E6: 496835 | F6: 76202 | G6: 0 | H6: 573037
B7: nizhnynovgorod | C7: =VLOOKUP(B7,'население 2023'!C:D,2,0) -> НиНо | D7: 0.089 | E7: 483540 | F7: 29437 | G7: 0 | H7: 518977
B8: rostovondon | C8: =VLOOKUP(B8,'население 2023'!C:D,2,0) -> РнД | D8: 0.031 | E8: 298373 | F8: 24087 | G8: 0 | H8: 322460
B9: krasnodar | C9: =VLOOKUP(B9,'население 2023'!C:D,2,0) -> Краснодар | D9: 0.014 | E9: 276300 | F9: 38621 | G9: 0 | H9: 314921
B10: perm | C10: =VLOOKUP(B10,'население 2023'!C:D,2,0) -> Пермь | D10: 0.085 | E10: 246662 | F10: 54031 | G10: 0 | H10: 305693
B11: kazan | C11: =VLOOKUP(B11,'население 2023'!C:D,2,0) -> Казань | D11: 0.028 | E11: 209530 | F11: 37619 | G11: 0 | H11: 247149
B12: samara | C12: =VLOOKUP(B12,'население 2023'!C:D,2,0) -> Самара | D12: 0.05 | E12: 163371 | F12: 52545 | G12: 0 | H12: 215916
B13: volgograd | C13: =VLOOKUP(B13,'население 2023'!C:D,2,0) -> Влг | D13: 0.086 | E13: 173514 | F13: 10760 | G13: 0 | H13: 184274
B14: sochi | C14: =VLOOKUP(B14,'население 2023'!C:D,2,0) -> Сочи | D14: 0.109 | E14: 88780 | F14: 42638 | G14: 0 | H14: 136465
B15: chelyabinsk | C15: =VLOOKUP(B15,'население 2023'!C:D,2,0) -> Члб | D15: 0.02 | E15: 112047 | F15: 15831 | G15: 0 | H15: 127878
... B103: nakhabino | C103: =VLOOKUP(B103,'население 2023'!C:D,2,0) -> #N/A | D103: 0 | E103: 0 | F103: 304 | G103: 0 | H103: 304

Sheet затраты 07.07
B2: https://datalens.yandex-team.ru/wbenuos6lxv4o-subsidy-details-advanced?tab=8Z&state=cc583fdb1134 | D2: неделя с 07.07
B3: Zone | C3: на русском | D3: sub/GMV | E3: dXgY | F3: MFG | G3: MFGgeo | H3: Substotal
B4: ekb | C4: =VLOOKUP(B4,'население 2023'!C:D,2,0) -> Екб | D4: 0.063 | E4: 855628 | F4: 21412 | G4: 0 | H4: 877040
B5: spb | C5: =VLOOKUP(B5,'население 2023'!C:D,2,0) -> СПб | D5: 0.011 | E5: 593670 | F5: 6043 | G5: 0 | H5: 599713
B6: novosibirsk | C6: =VLOOKUP(B6,'население 2023'!C:D,2,0) -> Нск | D6: 0.044 | E6: 547588 | F6: 124483 | G6: 0 | H6: 680574
B7: nizhnynovgorod | C7: =VLOOKUP(B7,'население 2023'!C:D,2,0) -> НиНо | D7: 0.082 | E7: 460734 | F7: 26875 | G7: 0 | H7: 487609
B8: krasnodar | C8: =VLOOKUP(B8,'население 2023'!C:D,2,0) -> Краснодар | D8: 0.021 | E8: 426600 | F8: 41430 | G8: 0 | H8: 468030
B9: rostovondon | C9: =VLOOKUP(B9,'население 2023'!C:D,2,0) -> РнД | D9: 0.03 | E9: 267994 | F9: 17883 | G9: 0 | H9: 285877
B10: perm | C10: =VLOOKUP(B10,'население 2023'!C:D,2,0) -> Пермь | D10: 0.086 | E10: 250382 | F10: 49825 | G10: 0 | H10: 300207
B11: kazan | C11: =VLOOKUP(B11,'население 2023'!C:D,2,0) -> Казань | D11: 0.025 | E11: 203270 | F11: 32284 | G11: 0 | H11: 235554
B12: volgograd | C12: =VLOOKUP(B12,'население 2023'!C:D,2,0) -> Влг | D12: 0.088 | E12: 179548 | F12: 12564 | G12: 0 | H12: 192112
B13: samara | C13: =VLOOKUP(B13,'население 2023'!C:D,2,0) -> Самара | D13: 0.043 | E13: 150974 | F13: 44420 | G13: 0 | H13: 195394
B14: omsk | C14: =VLOOKUP(B14,'население 2023'!C:D,2,0) -> Омск | D14: 0.053 | E14: 116796 | F14: 2971 | G14: 0 | H14: 119767
B15: chelyabinsk | C15: =VLOOKUP(B15,'население 2023'!C:D,2,0) -> Члб | D15: 0.018 | E15: 91713 | F15: 22115 | G15: 0 | H15: 113828
... B103: shakhty | C103: =VLOOKUP(B103,'население 2023'!C:D,2,0) -> Шахты | D103: 0.014 | E103: 0 | F103: 387 | G103: 0 | H103: 387

Sheet затраты 30.06
B2: https://datalens.yandex-team.ru/wbenuos6lxv4o-subsidy-details-advanced?tab=8Z&state=25c95e031134 | D2: неделя с 30.06
B3: Zone | C3: на русском | D3: sub/GMV | E3: dXgY | F3: MFG | G3: MFGgeo | H3: Substotal | I3: Итого
B4: ekb | C4: =VLOOKUP(B4,'население 2023'!C:D,2,0) -> Екб | D4: 0.058 | E4: 827573 | F4: 21756 | G4: 0 | H4: 851892 | I4: снизить цели
B5: spb | C5: =VLOOKUP(B5,'население 2023'!C:D,2,0) -> СПб | D5: 0.011 | E5: 599473 | F5: 9077 | G5: 0 | H5: 608550 | I5: цели 5т закончились 09.07, а что xl2?
B6: nizhnynovgorod | C6: =VLOOKUP(B6,'население 2023'!C:D,2,0) -> НиНо | D6: 0.091 | E6: 505612 | F6: 32658 | G6: 0 | H6: 538270 | I6: снизить цели
B7: novosibirsk | C7: =VLOOKUP(B7,'население 2023'!C:D,2,0) -> Нск | D7: 0.038 | E7: 468833 | F7: 114164 | G7: 0 | H7: 582997 | I7: добавить искл. тег и снизить мфг в m и l кузовах
B8: krasnodar | C8: =VLOOKUP(B8,'население 2023'!C:D,2,0) -> Краснодар | D8: 0.022 | E8: 447080 | F8: 25202 | G8: 0 | H8: 472282 | I8: сделали недельные цели xl2
B9: rostovondon | C9: =VLOOKUP(B9,'население 2023'!C:D,2,0) -> РнД | D9: 0.027 | E9: 258189 | F9: 23509 | G9: 0 | H9: 281698 | I9: пересмотр целей
B10: perm | C10: =VLOOKUP(B10,'население 2023'!C:D,2,0) -> Пермь | D10: 0.082 | E10: 219276 | F10: 50635 | G10: 0 | H10: 269911
B11: volgograd | C11: =VLOOKUP(B11,'население 2023'!C:D,2,0) -> Влг | D11: 0.097 | E11: 186176 | F11: 9938 | G11: 0 | H11: 196114 | I11: пересмотр целей
B12: kazan | C12: =VLOOKUP(B12,'население 2023'!C:D,2,0) -> Казань | D12: 0.024 | E12: 166300 | F12: 34508 | G12: 0 | H12: 200808 | I12: пересмотр целей и проверить МФГ
B13: samara | C13: =VLOOKUP(B13,'население 2023'!C:D,2,0) -> Самара | D13: 0.042 | E13: 137816 | F13: 41160 | G13: 0 | H13: 178976
B14: omsk | C14: =VLOOKUP(B14,'население 2023'!C:D,2,0) -> Омск | D14: 0.051 | E14: 111866 | F14: 3544 | G14: 0 | H14: 115410
B15: chelyabinsk | C15: =VLOOKUP(B15,'население 2023'!C:D,2,0) -> Члб | D15: 0.017 | E15: 83559 | F15: 17834 | G15: 0 | H15: 101393
B16: kaliningrad | C16: =VLOOKUP(B16,'население 2023'!C:D,2,0) -> Калининград | D16: 0.102 | E16: 82920 | F16: 21362 | G16: 0 | H16: 104282
B17: tumen | C17: =VLOOKUP(B17,'население 2023'!C:D,2,0) -> Тюмень | D17: 0.026 | E17: 70619 | F17: 7037 | G17: 0 | H17: 77656
B18: krasnoyarsk | C18: =VLOOKUP(B18,'население 2023'!C:D,2,0) -> Красноярск | D18: 0.038 | E18: 61526 | F18: 8245 | G18: 0 | H18: 69771
B19: saratov | C19: =VLOOKUP(B19,'население 2023'!C:D,2,0) -> Саратов | D19: 0.055 | E19: 60740 | F19: 26743 | G19: 0 | H19: 88541
B20: ufa | C20: =VLOOKUP(B20,'население 2023'!C:D,2,0) -> Уфа | D20: 0.022 | E20: 60021 | F20: 22978 | G20: 0 | H20: 82999
B21: stavropol | C21: =VLOOKUP(B21,'население 2023'!C:D,2,0) -> Ставрополь | D21: 0.227 | E21: 57727 | F21: 26025 | G21: 0 | H21: 83752 | I21: =IF(D21>15%,"???","") -> ???
B22: moscow | C22: =VLOOKUP(B22,'население 2023'!C:D,2,0) -> Москва | D22: 0.001 | E22: 56910 | F22: 35428 | G22: 1752 | H22: 101025
B23: voronezh | C23: =VLOOKUP(B23,'население 2023'!C:D,2,0) -> Воронеж | D23: 0.015 | E23: 37000 | F23: 8908 | G23: 0 | H23: 45908
B24: irkutsk | C24: =VLOOKUP(B24,'население 2023'!C:D,2,0) -> Иркутск | D24: 0.114 | E24: 34700 | F24: 5806 | G24: 0 | H24: 40506 | I24: =IF(D24>15%,"???","")
B25: astrakhan | C25: =VLOOKUP(B25,'население 2023'!C:D,2,0) -> Астрахань | D25: 0.147 | E25: 27500 | F25: 8423 | G25: 116 | H25: 36039 | I25: =IF(D25>15%,"???","")
B26: barnaul | C26: =VLOOKUP(B26,'население 2023'!C:D,2,0) -> Барнаул | D26: 0.162 | E26: 27391 | F26: 6217 | G26: 0 | H26: 33608 | I26: =IF(D26>15%,"???","") -> ???
B27: orel | C27: =VLOOKUP(B27,'население 2023'!C:D,2,0) -> Орел | D27: 0.137 | E27: 27100 | F27: 9733 | G27: 0 | H27: 36833 | I27: =IF(D27>15%,"???","")
B28: tula | C28: =VLOOKUP(B28,'население 2023'!C:D,2,0) -> Тула | D28: 0.097 | E28: 26200 | F28: 258 | G28: 0 | H28: 26458 | I28: =IF(D28>15%,"???","")
B29: orenburg | C29: =VLOOKUP(B29,'население 2023'!C:D,2,0) -> Оренбург | D29: 0.161 | E29: 23132 | F29: 6849 | G29: 0 | H29: 33781 | I29: =IF(D29>15%,"???","") -> ???
B30: vladivostok | C30: =VLOOKUP(B30,'население 2023'!C:D,2,0) -> Владивосток | D30: 0.123 | E30: 22485 | F30: 1570 | G30: 0 | H30: 24055 | I30: =IF(D30>15%,"???","")
B31: togliatti | C31: =VLOOKUP(B31,'население 2023'!C:D,2,0) -> Тольятти | D31: 0.155 | E31: 20300 | F31: 5038 | G31: 0 | H31: 25338 | I31: =IF(D31>15%,"???","") -> ???
B32: vologda | C32: =VLOOKUP(B32,'население 2023'!C:D,2,0) -> Вологда | D32: 0.276 | E32: 19571 | F32: 2322 | G32: 0 | H32: 21893 | I32: =IF(D32>15%,"???","") -> ???
B33: ryazan | C33: =VLOOKUP(B33,'население 2023'!C:D,2,0) -> Рязань | D33: 0.14 | E33: 19338 | F33: 1780 | G33: 0 | H33: 21118 | I33: =IF(D33>15%,"???","")
B34: krasnoe_selo | C34: =VLOOKUP(B34,'население 2023'!C:D,2,0) -> #N/A | D34: 0.013 | E34: 18610 | F34: 41 | G34: 0 | H34: 18651 | I34: =IF(D34>15%,"???","")
B35: ulianovsk | C35: =VLOOKUP(B35,'население 2023'!C:D,2,0) -> Ульяновск | D35: 0.104 | E35: 14771 | F35: 2441 | G35: 0 | H35: 17212 | I35: =IF(D35>15%,"???","")
... B37: cheboksary | C37: =VLOOKUP(B37,'население 2023'!C:D,2,0) -> Чебоксары | D37: 0.096 | E37: 13467 | F37: 980 | G37: 0 | H37: 14447 | I37: =IF(D37>15%,"???","")
B38: sochi | C38: =VLOOKUP(B38,'население 2023'!C:D,2,0) -> Сочи | D38: 0.04 | E38: 12859 | F38: 38138 | G38: 0 | H38: 50997
B39: volzhskiy | C39: =VLOOKUP(B39,'население 2023'!C:D,2,0) -> Волжский | D39: 0.054 | E39: 12752 | F39: 1423 | G39: 0 | H39: 14175 | I39: =IF(D39>15%,"???","")
B40: akademgorod | C40: =VLOOKUP(B40,'население 2023'!C:D,2,0) -> #N/A | D40: 0.018 | E40: 11103 | F40: 2808 | G40: 0 | H40: 13911 | I40: =IF(D40>15%,"???","")
B41: ivanovo | C41: =VLOOKUP(B41,'население 2023'!C:D,2,0) -> Иваново | D41: 0.158 | E41: 10917 | F41: 20060 | G41: 0 | H41: 30977 | I41: =IF(D41>15%,"???","") -> ???
B42: izhevsk | C42: =VLOOKUP(B42,'население 2023'!C:D,2,0) -> Ижевск | D42: 0.09 | E42: 9555 | F42: 2426 | G42: 0 | H42: 11981 | I42: =IF(D42>15%,"???","")
...

Sheet Итого. субсидии
D2: Параметры целей | L2: Метрики крайней недели
D3: Текущие цели | H3: Предыдущие цели | M3: Из выгрузки | O3: Из доходимости (без отсева) | T3: Файл города
B4: Город | C4: Кузов / Опция | D4: Дата запуска | E4: Дата закрытия | F4: Время работы | G4: Лесенка | H4: Дата запуска | I4: Дата закрытия | J4: Лесенка | K4: dxgy города с 21.07 | L4: крайняя неделя | M4: CDR | N4: NI/GMV опции | O4: SR | P4: SR 3 ступени | Q4: sub dxgy | R4: sub dxgy / gmv опции | S4: sub dxgy / gmv total | T4: Ссылка | U4: Кто? | V4: Итог | W4: Экипажи и опция | X4: Квот в неделю
B5: Мск | C5: XXL2 | D5: 04.08 (ПН) | F5: 7-10 | G5: 2 - 3 500 3 - 7 500 | T5: https://docs.google.com/spreadsheets/d/1L0y7ob_1Aq6VlMgj15NmCKz4X6XGx90-gYNb6ULAbb8/edit?gid=0#gid=0 | U5: Аня | V5: с 04.08 запустили, пока наблюдаем
B6: СПб | C6: XL2 | D6: 19.06 (ЧТ) | E6: - | F6: 7-10 | G6: 16 - 6000 23 - 12000 30 - 20000 | I6: 05.08(ВТ) | J6: 2 - 1200 3 - 2500 4 - 4000 | K6: =VLOOKUP($B6,'затраты 21.07'!$C:$E,3,0) -> 756818 | L6: 45859 | M6: 0.73 | N6: 0.07 | O6: 0.61 | P6: 0.1 | Q6: 616700 | R6: 0.468 | S6: 0.01 | T6: https://docs.google.com/spreadsheets/d/1czRoI-UDhvvJur9xfSI1PxPVCvuaZ04gs3XWKWhPxOQ/edit?gid=0#gid=0 | U6: Илья | V6: с 04.08 перевели на недельные | W6: нет
B7: СПб | C7: XXL | D7: 16.07 (СР) | E7: - | F7: 7-10 | G7: 2- 2000 3- 4000 4- 6000 | H7: 18.06 (СР) | I7: 09.07 (СР) | J7: 2 - 2000 3 - 3000 | K7: =VLOOKUP($B7,'затраты 21.07'!$C:$E,3,0) -> 756818 | L7: 45859 | M7: 0.69 | N7: 0.1 | O7: 0.37 | P7: 0.03 | Q7: 189000 | R7: 0.246 | S7: 0.003 | T7: https://docs.google.com/spreadsheets/d/1czRoI-UDhvvJur9xfSI1PxPVCvuaZ04gs3XWKWhPxOQ/edit?gid=1949845219#gid=1949845219 | U7: Илья | V7: с 04.08 повысили | W7: нет
B8: Екб | C8: S | D8: 10.06 (ВТ) | E8: 45860 | F8: 0-0 | G8: 25 - 2200 35 - 3500 45 - 5000 | H8: 10.06 (ВТ) | I8: 22.07 (ВТ) | J8: 25 - 2200 35 - 3500 45 - 5000 | K8: =VLOOKUP($B8,'затраты 21.07'!$C:$E,3,0) -> 698190 | L8: 45860 | M8: 0.92 | N8: 0.14 | O8: 0.21 | P8: 0.06 | Q8: 0 | R8: 0 | S8: 0 | T8: https://docs.google.com/spreadsheets/d/1GSOUyFNsvVQA-Q_TCpoHkGeW96anrZpdU3rS3pGOfuI/edit?gid=1203612246#gid=1203612246 | U8: Илья | V8: с 22.07 закрыли и запустили на s2 | W8: нет
B9: Екб | C9: S2 | D9: 22.07 (ВТ) | E9: - | F9: 0-0 | G9: 18 - 3500 24 - 5000 30 - 7000 | K9: =VLOOKUP($B9,'затраты 21.07'!$C:$E,3,0) -> 698190 | L9: 45860 | M9: 0.81 | N9: 0.13 | O9: 0.47 | P9: 0.24 | Q9: 45000 | R9: 0.333 | S9: 0.003 | T9: https://docs.google.com/spreadsheets/d/1GSOUyFNsvVQA-Q_TCpoHkGeW96anrZpdU3rS3pGOfuI/edit?gid=1203612246#gid=1203612246 | U9: Илья | V9: с 22.07 запустили | W9: нет
B10: Екб | C10: M | D10: 06.06 (ПТ) | E10: - | F10: 0-0 | G10: 18 - 3000 24 - 4800 30 - 6900 | K10: =VLOOKUP($B10,'затраты 21.07'!$C:$E,3,0) -> 698190 | L10: 45863 | M10: 0.93 | N10: 0.1 | O10: 0.21 | P10: 0.04 | Q10: 242600 | R10: 0.043 | S10: 0.017 | T10: https://docs.google.com/spreadsheets/d/1GSOUyFNsvVQA-Q_TCpoHkGeW96anrZpdU3rS3pGOfuI/edit?gid=689502523#gid=689502523 | U10: Илья | V10: c 18.07 усложнили, снизив доплаты с 08.08 закрыли и запустили цели на m2 | W10: нет
B11: Екб | C11: M2 | V11: с 08.08 запустили
B12: Екб | C12: L | D12: 06.06 (ПТ) | E12: - | F12: 0-0 | G12: 15 - 3000 20 - 4800 25 - 7000 | K12: =VLOOKUP($B12,'затраты 21.07'!$C:$E,3,0) -> 698190 | L12: 45863 | M12: 0.91 | N12: 0.13 | O12: 0.28 | P12: 0.12 | Q12: 0 | R12: 0 | S12: 0 | T12: https://docs.google.com/spreadsheets/d/1GSOUyFNsvVQA-Q_TCpoHkGeW96anrZpdU3rS3pGOfuI/edit?gid=1825489637#gid=1825489637 | U12: Илья | V12: c 25.07 закрыли | W12: 4.0 L2 | X12: 28
B13: Екб | C13: XL2 | D13: 16.06 (ПН) | E13: - | F13: 0-0 | G13: 2 - 1800 3 - 3600 | K13: =VLOOKUP($B13,'затраты 21.07'!$C:$E,3,0) -> 698190 | L13: 45859 | M13: 0.76 | N13: 0.06 | O13: 0.62 | P13: 0.24 | Q13: 226800 | R13: 0.719 | S13: 0.017 | T13: https://docs.google.com/spreadsheets/d/1GSOUyFNsvVQA-Q_TCpoHkGeW96anrZpdU3rS3pGOfuI/edit?gid=648592715#gid=648592715 | U13: Илья | V13: c 04.08 перевели на недельные | W13: нет
B14: Екб | C14: XXL | D14: 09.06 (ПН) | E14: - | F14: 8-10 | G14: 2 - 3000 3 - 4000 4 - 5000 | H14: до 26.05 | J14: 2 - 2000 3 - 3000 4 - 4000 | K14: =VLOOKUP($B14,'затраты 21.07'!$C:$E,3,0) -> 698190 | L14: 45859 | M14: 0.71 | N14: 0.09 | O14: 0.08 | P14: 0 | Q14: 21000 | R14: 0.099 | S14: 0.002 | T14: https://docs.google.com/spreadsheets/d/1GSOUyFNsvVQA-Q_TCpoHkGeW96anrZpdU3rS3pGOfuI/edit?gid=1784196008#gid=1784196008 | U14: Илья | V14: c 04.08 скорректировали | W14: нет
B15: НиНо | C15: M | D15: 06.06 (ПТ) | E15: - | F15: 0-0 | G15: 20 - 3000 25 - 4000 30 - 6000 | K15: =VLOOKUP($B15,'затраты 21.07'!$C:$E,3,0) -> 475066 | L15: 45856 | M15: 0.79 | N15: 0.1 | O15: 0.17 | P15: 0.08 | Q15: 90000 | R15: 0.029 | S15: 0.013 | T15: https://docs.google.com/spreadsheets/d/16MDhDw0nOzJBuAupcd5ZcgtQ7xKgEeScEm9A-AyXTMc/edit?gid=0#gid=0 | U15: Аня | V15: поддерживаем водителей (проблемы со связью и погода) | W15: 4.0 M2 | X15: 18
B16: НиНо | C16: L | D16: 06.06 (ПТ) | E16: - | F16: 0-0 | G16: 15 - 2700 20 - 4000 25 - 6000 | K16: =VLOOKUP($B16,'затраты 21.07'!$C:$E,3,0) -> 475066 | L16: 45856 | M16: 0.75 | N16: 0.08 | O16: 0.21 | P16: 0.08 | Q16: 78300 | R16: 0.048 | S16: 0.011 | T16: https://docs.google.com/spreadsheets/d/16MDhDw0nOzJBuAupcd5ZcgtQ7xKgEeScEm9A-AyXTMc/edit?gid=136358845#gid=136358845 | U16: Аня | V16: поддерживаем водителей (проблемы со связью и погода) | W16: 4.0 L2 | X16: 41
B17: НиНо | C17: XL2 | D17: 20.06 (ПТ) | F17: 8-10 | G17: 7- 3500 12- 6000 17- 9000 | I17: 01.08 (ПТ) | J17: 2 - 1500 3 - 3000 | K17: =VLOOKUP($B17,'затраты 21.07'!$C:$E,3,0) -> 475066 | L17: 45856 | M17: 0.75 | N17: 0.09 | O17: 0.71 | P17: 0.29 | Q17: 88200 | R17: 0.992 | S17: 0.012 | T17: https://docs.google.com/spreadsheets/d/16MDhDw0nOzJBuAupcd5ZcgtQ7xKgEeScEm9A-AyXTMc/edit?gid=777348995#gid=777348995 | U17: Аня | V17: с 01.08 перевели на недельные
B18: НиНо | C18: XXL | D18: 26.05 (ПН) | E18: - | F18: 8-10 | G18: 2 - 2500 3 - 4000 4 - 6000 | K18: =VLOOKUP($B18,'затраты 21.07'!$C:$E,3,0) -> 475066 | L18: 45856 | M18: 0.74 | N18: 0 | O18: 1 | P18: 0.33 | Q18: 25000 | R18: 0.386 | S18: 0.003 | T18: https://docs.google.com/spreadsheets/d/16MDhDw0nOzJBuAupcd5ZcgtQ7xKgEeScEm9A-AyXTMc/edit?gid=545071466#gid=545071466 | U18: Аня | V18: пока норм | W18: 3.0 | X18: 14
B19: Нск | C19: S | D19: 10.06 (ВТ) | E19: 22.07 (ВТ) | F19: 0-0 | G19: 32 - 3000 42 - 4500 52 - 6000 | K19: =VLOOKUP($B19,'затраты 21.07'!$C:$E,3,0) -> 321639 | L19: 45846 | M19: 0.93 | N19: 0.11 | O19: 0.17 | P19: 0.06 | Q19: 223500 | R19: 0.042 | S19: 0.014 | T19: https://docs.google.com/spreadsheets/d/1iA1pnBTSGLeEVcD669DyUKOptWEry9G75QplhINUT_8/edit?gid=52078899#gid=52078899 | U19: Ира | V19: с 22.07 закрыли и запустили цели на s2 | W19: нет
B20: Нск | C20: S2 | D20: 22.07 (ВТ) | F20: 0-0 | G20: 15 - 2200 20 - 3800 25 - 5800 | K20: =VLOOKUP($B20,'затраты 21.07'!$C:$E,3,0) -> 321639 | L20: 45860 | M20: 0.78 | N20: 0.15 | O20: 0.47 | P20: 0.18 | Q20: 34800 | R20: 0.317 | S20: 0.002 | T20: https://docs.google.com/spreadsheets/d/1iA1pnBTSGLeEVcD669DyUKOptWEry9G75QplhINUT_8/edit?gid=644584907#gid=644584907 | U20: Ира | V20: с 22.07 запустили | W20: нет
B21: Нск | C21: M1 | D21: 18.06 (СР) | E21: - | F21: 0-0 | G21: 30 - 3000 35 - 4000 40 - 5000 | K21: =VLOOKUP($B21,'затраты 21.07'!$C:$E,3,0) -> 321639 | L21: 45861 | M21: 0.89 | N21: 0.13 | O21: 0.05 | P21: 0.02 | Q21: 17000 | R21: 0.017 | S21: 0.001 | T21: https://docs.google.com/spreadsheets/d/1iA1pnBTSGLeEVcD669DyUKOptWEry9G75QplhINUT_8/edit?gid=1949640804#gid=1949640804 | U21: Ира | V21: пока норм (внимательно на след. неделе) | W21: нет
B22: Нск | C22: M2 | D22: 18.06 (СР) | E22: - | F22: 0-0 | G22: 20 - 4000 25 - 5200 30 - 7000 | K22: =VLOOKUP($B22,'затраты 21.07'!$C:$E,3,0) -> 321639 | L22: 45861 | M22: 0.85 | N22: 0.07 | O22: 0.43 | P22: 0.25 | Q22: 69000 | R22: 0.086 | S22: 0.004 | T22: https://docs.google.com/spreadsheets/d/1iA1pnBTSGLeEVcD669DyUKOptWEry9G75QplhINUT_8/edit?gid=1980684084#gid=1980684084 | U22: Ира | V22: пока норм | W22: нет
B23: Нск | C23: L1 | D23: 18.06 (СР) | E23: - | F23: 0-0 | G23: 25 - 3200 30 - 4000 35 - 5200 | K23: =VLOOKUP($B23,'затраты 21.07'!$C:$E,3,0) -> 321639 | L23: 45861 | M23: 0.79 | N23: 0.11 | O23: 0.21 | P23: 0.08 | Q23: 20000 | R23: 0.055 | S23: 0.001 | T23: https://docs.google.com/spreadsheets/d/1iA1pnBTSGLeEVcD669DyUKOptWEry9G75QplhINUT_8/edit?gid=934551811#gid=934551811 | U23: Ира | V23: пока норм | W23: 4.0 L2 | X23: 35
B24: Нск | C24: L2 | D24: 23.07 (СР) | E24: - | F24: 0-0 | G24: 20 - 5500 25 - 7000 30 - 8500 | H24: 18.06 (СР) | J24: 20 - 4500 25 - 6000 30 - 7500 | K24: =VLOOKUP($B24,'затраты 21.07'!$C:$E,3,0) -> 321639 | L24: 45861 | M24: 0.78 | N24: 0.04 | O24: 0.29 | P24: 0.07 | Q24: 51500 | R24: 0.083 | S24: 0.003 | T24: https://docs.google.com/spreadsheets/d/1iA1pnBTSGLeEVcD669DyUKOptWEry9G75QplhINUT_8/edit?gid=552174696#gid=552174696 | U24: Ира | V24: с 23.07 подняли бонусы на 1к | W24: 4.0 L2 | X24: 35
B25: Нск | C25: XXL | D25: 26.05 (ПН) | E25: - | F25: 8-10 | G25: 2 - 2000 3 - 3000 4 - 4000 | K25: =VLOOKUP($B25,'затраты 21.07'!$C:$E,3,0) -> 321639 | L25: 45866 | M25: 0.76 | N25: 0.05 | O25: 0.8 | P25: 0.4 | Q25: 98000 | R25: 0.581 | S25: 0.006 | T25: https://docs.google.com/spreadsheets/d/1iA1pnBTSGLeEVcD669DyUKOptWEry9G75QplhINUT_8/edit?gid=1987691835#gid=1987691835 | U25: Ира | V25: норм | W25: нет
B26: Краснодар | C26: XL2 | D26: 14.07 (ПН) | E26: - | F26: 0-0 | G26: 10 - 4000 15 - 6700 20 - 10000 | H26: 16.06 (ПН) | I26: 14.07 (ПН) | J26: 2 - 1800 3 - 3600 | K26: =VLOOKUP($B26,'затраты 21.07'!$C:$E,3,0) -> 253000 | L26: 45866 | M26: 0.75 | N26: 0.07 | O26: 0.55 | P26: 0.23 | Q26: 120800 | R26: 0.242 | S26: 0.006 | T26: https://docs.google.com/spreadsheets/d/1TuWobhfnRPIiTHBvnE25v82b1WFheH4ZP7MAwtDgQm4/edit?gid=0#gid=0 | U26: Илья | V26: с 14.07 перевели на дешевые недельные | W26: нет
B27: Краснодар | C27: XXL | D27: 04.08(ПН) | E27: - | F27: 8-10 | G27: 2 - 3000 3 - 5000 4 - 6000 | H27: 25.04 (ПТ) | K27: =VLOOKUP($B27,'затраты 21.07'!$C:$E,3,0) -> 253000 | L27: 45866 | M27: 0.8 | N27: 0 | O27: 0.5 | P27: 0 | Q27: 287000 | R27: 0.501 | S27: 0.014 | T27: https://docs.google.com/spreadsheets/d/1TuWobhfnRPIiTHBvnE25v82b1WFheH4ZP7MAwtDgQm4/edit?gid=182988229#gid=182988229 | U27: Илья | V27: с 04.08 перевели на недельные | W27: нет
B28: Пермь | C28: M | D28: 18.06 (СР) | E28: - | F28: 0-0 | G28: 16 - 3100 21 - 4500 26 - 5800 | K28: =VLOOKUP($B28,'затраты 21.07'!$C:$E,3,0) -> 246709 | L28: 45847 | M28: 0.91 | N28: 0.04 | O28: 0.34 | P28: 0.18 | Q28: 150400 | R28: 0.086 | S28: 0.042 | T28: https://docs.google.com/spreadsheets/d/1vNDpP86H9Ix43HThliS4SflbtuEXzIeeJUFv5YooVuo/edit?gid=0#gid=0 | U28: Ира | V28: с 30.07 закрыли | W28: 4.0 M2 | X28: 6
B29: Пермь | C29: М2 | D29: 28.07 (ПН) | F29: 0-0 | G29: 15 - 4000 20 - 5500 25 - 8000 | K29: =VLOOKUP($B29,'затраты 21.07'!$C:$E,3,0) -> 246709 | L29: 45866 | M29: 0.9 | N29: 0.03 | O29: 0.36 | P29: 0.14 | Q29: 28000 | R29: 0.129 | S29: 0.007 | T29: https://docs.google.com/spreadsheets/d/1vNDpP86H9Ix43HThliS4SflbtuEXzIeeJUFv5YooVuo/edit?gid=1894564267#gid=1894564267 | U29: Ира | V29: с 28.07 запустили, ждем первые недели | W29: 4.0 M2 | X29: 6
B30: Пермь | C30: L | D30: 18.06 (СР) | E30: - | F30: 0-0 | G30: 15 - 3500 20 - 5000 25 - 7000 | K30: =VLOOKUP($B30,'затраты 21.07'!$C:$E,3,0) -> 246709 | L30: 45861 | M30: 0.91 | N30: 0.09 | O30: 0.33 | P30: 0.1 | Q30: 86000 | R30: 0.111 | S30: 0.024 | T30: https://docs.google.com/spreadsheets/d/1vNDpP86H9Ix43HThliS4SflbtuEXzIeeJUFv5YooVuo/edit?gid=1675272907#gid=1675272907 | U30: Ира | V30: норм | W30: нет
B31: Пермь | C31: L2 | D31: 04.08 (ПН) | F31: 0-0 | G31: 10 - 4000 15 - 7000 20 - 10000 | K31: =VLOOKUP($B31,'затраты 21.07'!$C:$E,3,0) -> 246709 | T31: https://docs.google.com/spreadsheets/d/1vNDpP86H9Ix43HThliS4SflbtuEXzIeeJUFv5YooVuo/edit?gid=846966812#gid=846966812 | U31: Ира | V31: с 04.08 запустили | W31: нет
B32: Казань | C32: XXL | D32: 10.06 (ВТ) | E32: - | F32: 45938 | G32: 2 - 2000 3 - 3000 4 - 4000 | K32: =VLOOKUP($B32,'затраты 21.07'!$C:$E,3,0) -> 203000 | L32: 45860 | M32: 0.84 | N32: 0.04 | O32: 0.2 | P32: 0 | Q32: 56000 | R32: 0.607 | S32: 0.006 | T32: https://docs.google.com/spreadsheets/d/1OqzNl9qrNvyJyfxhZgbB7gQpJqh63bSXw8g1V34SDl4/edit?gid=0#gid=0 | U32: Илья | V32: c 07.08 повысили бонусы | W32: 3.0 XXL0 | X32: 21
B33: Самара | C33: S2 | D33: 18.06 (СР) | E33: - | F33: 0-0 | G33: 14 - 2500 19 - 3500 24 - 4800 | K33: =VLOOKUP($B33,'затраты 21.07'!$C:$E,3,0) -> 198851 | L33: 45861 | M33: 0.8 | N33: 0.11 | O33: 0.5 | P33: 0.25 | Q33: 30000 | R33: 0.338 | S33: 0.007 | T33: https://docs.google.com/spreadsheets/d/1N92gj8zaiRTTIOlHH0d-jqlQXdXx47QqJ7X_p4JnLJs/edit?gid=95711931#gid=95711931 | U33: Илья | V33: с 23.07 повысили бонусы | W33: нет
B34: Самара | C34: M2 | D34: 18.06 (СР) | E34: - | F34: 0-0 | G34: 15 - 3000 20 - 4500 25 - 5900 | K34: =VLOOKUP($B34,'затраты 21.07'!$C:$E,3,0) -> 198851 | L34: 45861 | M34: 0.8 | N34: 0.08 | O34: 0.45 | P34: 0.27 | Q34: 29800 | R34: 0.098 | S34: 0.007 | T34: https://docs.google.com/spreadsheets/d/1N92gj8zaiRTTIOlHH0d-jqlQXdXx47QqJ7X_p4JnLJs/edit?gid=35461677#gid=35461677 | U34: Илья | V34: с 23.07 повысили бонусы | W34: нет
B35: Самара | C35: L | D35: 18.06 (СР) | E35: - | F35: 0-0 | G35: 20 - 4000 25 - 5000 30 - 6500 | K35: =VLOOKUP($B35,'затраты 21.07'!$C:$E,3,0) -> 198851 | L35: 45861 | M35: 0.87 | N35: 0.12 | O35: 0.21 | P35: 0.03 | Q35: 0 | R35: 0 | S35: 0 | T35: https://docs.google.com/spreadsheets/d/1N92gj8zaiRTTIOlHH0d-jqlQXdXx47QqJ7X_p4JnLJs/edit?gid=1230488956#gid=1230488956 | U35: Илья | V35: с 30.07 закрыть для l и запустить на l1 | W35: нет
B36: Самара | C36: L1 | D36: 30.07 (СР) | F36: 0-0 | G36: 18 - 4000 26 - 6000 34 - 8000 | K36: =VLOOKUP($B36,'затраты 21.07'!$C:$E,3,0) -> 198851 | L36: 45861 | M36: 0.82 | N36: 0.14 | O36: 0.29 | P36: 0 | Q36: 8000 | R36: 0.102 | S36: 0.002 | T36: https://docs.google.com/spreadsheets/d/1N92gj8zaiRTTIOlHH0d-jqlQXdXx47QqJ7X_p4JnLJs/edit?gid=1760356234#gid=1760356234 | U36: Илья | V36: с 30.07 запустили
B37: Самара | C37: L2 | D37: 14.07 (ПН) | E37: - | F37: 45938 | G37: 7 - 2500 11 - 4000 15 - 6000 | H37: 24.03 (ПН) | I37: 14.07 (ПН) | J37: 6 - 2000 9 - 3500 12 - 5000 | K37: =VLOOKUP($B37,'затраты 21.07'!$C:$E,3,0) -> 198851 | L37: 45859 | M37: 0.59 | N37: 0.08 | O37: 0.8 | P37: 0.8 | Q37: 24000 | R37: 0.245 | S37: 0.005 | T37: https://docs.google.com/spreadsheets/d/1N92gj8zaiRTTIOlHH0d-jqlQXdXx47QqJ7X_p4JnLJs/edit?gid=643337644#gid=643337644 | U37: Илья | V37: с 14.07 подняли лесенку с 04.08 подняли лесенку | W37: нет
B38: Самара | C38: XL | D38: 18.06 (СР) | E38: - | F38: 0-0 | G38: 20 - 4500 25 - 5800 30 - 7000 | K38: =VLOOKUP($B38,'затраты 21.07'!$C:$E,3,0) -> 198851 | L38: 45861 | M38: 0.75 | N38: 0.15 | O38: 0.15 | P38: 0.12 | Q38: 32500 | R38: 0.176 | S38: 0.008 | T38: https://docs.google.com/spreadsheets/d/1N92gj8zaiRTTIOlHH0d-jqlQXdXx47QqJ7X_p4JnLJs/edit?gid=1880382121#gid=1880382121 | U38: Илья | V38: с 06.08 упростили, повысив доплаты | W38: нет
B39: РнД | C39: M2 | D39: 17.06 (ВТ) | E39: - | F39: 0-0 | G39: 15 - 3500 20 - 5000 25 - 6500 | H39: 29.07(ВТ) | J39: 20-5000 25-7000 30-9000 | K39: =VLOOKUP($B39,'затраты 21.07'!$C:$E,3,0) -> 177603 | L39: 45846 | M39: 0.78 | N39: 0.12 | O39: 0.37 | P39: 0.15 | Q39: 53000 | R39: 0.185 | S39: 0.008 | T39: https://docs.google.com/spreadsheets/d/18AVdPrLcJZrUzdQEUvrE4fCsoubl_u2WBWKPLhsb6R8/edit?gid=0#gid=0 | U39: Аня | V39: c 29.07 усложнили лесенку+повысили бонусы | W39: нет
B40: РнД | C40: L2 | D40: 17.06 (ВТ) | E40: - | F40: 0-0 | G40: 15 - 4000 20 - 5500 25 - 7000 | H40: 29.07(ВТ) | J40: 20-5500 25-7500 30-10000 | K40: =VLOOKUP($B40,'затраты 21.07'!$C:$E,3,0) -> 177603 | L40: 45846 | M40: 0.85 | N40: 0.17 | O40: 0.39 | P40: 0.11 | Q40: 37000 | R40: 0.103 | S40: 0.005 | T40: https://docs.google.com/spreadsheets/d/18AVdPrLcJZrUzdQEUvrE4fCsoubl_u2WBWKPLhsb6R8/edit?gid=108554741#gid=108554741 | U40: Аня | V40: c 29.07 усложнили лесенку+повысили бонусы | W40: нет
B41: РнД | C41: XL2 | D41: 22.07(ВТ) | E41: - | F41: 0-0 | G41: 7 -3000 12 -5500 17 -8500 | H41: 16.06 (ПН) | I41: 21.07(ПН) | J41: 2 - 1800 3 - 3600 | K41: =VLOOKUP($B41,'затраты 21.07'!$C:$E,3,0) -> 177603 | L41: 45846 | M41: 0.66 | N41: 0.02 | O41: 0.36 | P41: 0.09 | Q41: 63000 | R41: 1.247 | S41: 0.009 | T41: https://docs.google.com/spreadsheets/d/18AVdPrLcJZrUzdQEUvrE4fCsoubl_u2WBWKPLhsb6R8/edit?gid=188909213#gid=188909213 | U41: Аня | V41: с 22.07 перевели на недельные цели возможно, с 5 поднять бонусы | W41: нет
...

Sheet население 2023
B2: Агломерация / город | C2: Зона / город | D2: Город (рус) | E2: Тип города | F2: Топ по населению | G2: Популяция | H2: Расположение от центра | I2: Км от центра | J2: Субъект РФ, в состав которого входит город | K2: Население, тыс (2023 год)
B3: Moscow | C3: moscow | D3: Москва | E3: Москва | F3: 1 | G3: Москва | H3: Центр | I3: 0 | J3: Город федерального значения Москва | K3: 13104
B4: Saint-Petersburg | C4: spb | D4: СПб | E4: СПб | F4: 2 | G4: СПб | H4: Центр | I4: 0 | J4: Город федерального значения Санкт-Петербург | K4: 5400
B5: Novosibirsk | C5: novosibirsk | D5: Нск | E5: Кор | F5: 3 | G5: 1 млн+ | H5: Центр | I5: 0 | J5: Новосибирская область | K5: 1635
B6: Ekaterinburg | C6: ekb | D6: Екб | E6: Кор | F6: 4 | G6: 1 млн+ | H6: Центр | I6: 0 | J6: Свердловская область | K6: 1539
B7: Kazan | C7: kazan | D7: Казань | E7: Кор | F7: 5 | G7: 1 млн+ | H7: Центр | I7: 0 | J7: Республика Татарстан | K7: 1315
B8: Nizhny Novgorod | C8: nizhnynovgorod | D8: НиНо | E8: Кор | F8: 6 | G8: 1 млн+ | H8: Центр | I8: 0 | J8: Нижегородская область | K8: 1213
B9: Krasnoyarsk | C9: krasnoyarsk | D9: Красноярск | E9: Кор | F9: 7 | G9: 1 млн+ | H9: Центр | I9: 0 | J9: Красноярский край | K9: 1197
B10: Chelyabinsk | C10: chelyabinsk | D10: Члб | E10: Кор | F10: 8 | G10: 1 млн+ | H10: Центр | I10: 0 | J10: Челябинская область | K10: 1183
B11: Samara | C11: samara | D11: Самара | E11: Кор | F11: 9 | G11: 1 млн+ | H11: Центр | I11: 0 | J11: Самарская область | K11: 1164
B12: Ufa | C12: ufa | D12: Уфа | E12: Кор | F12: 10 | G12: 1 млн+ | H12: Центр | I12: 0 | J12: Республика Башкортостан | K12: 1158
B13: Rostov-on-Don | C13: rostovondon | D13: РнД | E13: Кор | F13: 11 | G13: 1 млн+ | H13: Центр | I13: 0 | J13: Ростовская область | K13: 1136
B14: Krasnodar | C14: krasnodar | D14: Краснодар | E14: Кор | F14: 12 | G14: 1 млн+ | H14: Центр | I14: 0 | J14: Краснодарский край | K14: 1121
... B20: Tyumen | C20: tumen | D20: Тюмень | E20: Кор | F20: 18 | G20: 800+ | H20: Центр | I20: 0 | J20: Тюменская область без автономных округов | K20: 856
B21: Togliatti | C21: togliatti | D21: Тольятти | E21: остальные | F21: 19 | G21: 600+ | H21: Центр | I21: 0 | J21: Самарская область | K21: 675
B22: Barnaul | C22: barnaul | D22: Барнаул | E22: остальные | F22: 20 | G22: 600+ | H22: Центр | I22: 0 | J22: Алтайский край | K22: 623
B23: Makhachkala | C23: makhachkala | D23: Макхачкала | E23: остальные | F23: 21 | G23: 600+ | H23: Центр | I23: 0 | J23: Республика Дагестан | K23: 623
B24: Izhevsk | C24: izhevsk | D24: Ижевск | E24: остальные | F24: 22 | G24: 600+ | H24: Центр | I24: 0 | J24: Удмуртская Республика | K24: 621
B25: Khabarovsk | C25: khabarovsk | D25: Хабаровск | E25: остальные | F25: 23 | G25: 600+ | H25: Центр | I25: 0 | J25: Хабаровский край | K25: 617
B26: Ulianovsk | C26: ulianovsk | D26: Ульяновск | E26: остальные | F26: 24 | G26: 600+ | H26: Центр | I26: 0 | J26: Ульяновская область | K26: 613
B27: Irkutsk | C27: irkutsk | D27: Иркутск | E27: остальные | F27: 25 | G27: 600+ | H27: Центр | I27: 0 | J27: Иркутская область | K27: 611
B28: Vladivostok | C28: vladivostok | D28: Владивосток | E28: остальные | F28: 26 | G28: 500+ | H28: Центр | I28: 0 | J28: Приморский край | K28: 597
B29: Yaroslavl | C29: yaroslavl | D29: Ярославль | E29: остальные | F29: 27 | G29: 500+ | H29: Центр | I29: 0 | J29: Ярославская область | K29: 571
B30: - | C30: севастополь | D30: Севастополь | E30: остальные | F30: 28 | G30: 500+ | H30: Центр | I30: 0 | J30: Город федерального значения Севастополь | K30: 558
B31: Tomsk | C31: tomsk | D31: Томск | E31: остальные | F31: 29 | G31: 500+ | H31: Центр | I31: 0 | J31: Томская область | K31: 552
B32: Stavropol | C32: stavropol | D32: Ставрополь | E32: остальные | F32: 30 | G32: 500+ | H32: Центр | I32: 0 | J32: Ставропольский край | K32: 550
... B45: Tula | C45: tula | D45: Тула | E45: остальные | F45: 43 | G45: 400+ | H45: Центр | I45: 0 | J45: Тульская область | K45: 467
B46: Sochi | C46: sochi | D46: Сочи | E46: Кор | F46: 44 | G46: 400+ | H46: Центр | I46: 0 | J46: Краснодарский край | K46: 447
D47: Красная поляна
B48: - | C48: ulanude | D48: Улан-Удэ | E48: остальные | F48: 45 | G48: 400+ | H48: Центр | I48: 0 | J48: Республика Бурятия | K48: 436
B49: Kursk | C49: kursk | D49: Курск | E49: остальные | F49: 46 | G49: 400+ | H49: Центр | I49: 0 | J49: Курская область | K49: 435
B50: Tver | C50: tver | D50: Тверь | E50: остальные | F50: 47 | G50: 400+ | H50: Центр | I50: 0 | J50: Тверская область | K50: 415
B51: Magnitogorsk | C51: magnitogorsk | D51: Магнитогорск | E51: остальные | F51: 48 | G51: 400+ | H51: Центр | I51: 0 | J51: Челябинская область | K51: 409
B52: Surgut | C52: surgut | D52: Сургут | E52: остальные | F52: 49 | G52: 400+ | H52: Центр | I52: 0 | J52: Ханты-Мансийский автономный округ - Югра | K52: 407
B53: Bryansk | C53: bryansk | D53: Брянск | E53: остальные | F53: 50 | G53: 300+ | H53: Центр | I53: 0 | J53: Брянская область | K53: 376
B54: - | C54: yakutsk | D54: Якутск | E54: остальные | F54: 51 | G54: 300+ | H54: Центр | I54: 0 | J54: Республика Саха (Якутия) | K54: 361
B55: Ivanovo | C55: ivanovo | D55: Иваново | E55: остальные | F55: 52 | G55: 300+ | H55: Центр | I55: 0 | J55: Ивановская область | K55: 361
B56: Vladimir | C56: vladimir | D56: Владимир | E56: остальные | F56: 53 | G56: 300+ | H56: Центр | I56: 0 | J56: Владимирская область | K56: 347
B57: - | C57: симферополь | D57: Симферополь | E57: остальные | F57: 54 | G57: 300+ | H57: Центр | I57: 0 | J57: Республика Крым | K57: 338
B58: Nizhny Tagil | C58: nizhnytagil | D58: Нижний Тагил | E58: остальные | F58: 55 | G58: 300+ | H58: Центр | I58: 0 | J58: Свердловская область | K58: 334
...

Sheet Город+опция
A1: Zone | B1: Fire | C1: Статус | D1: Кто | F1: Цвет | G1: Статус
A2: Krasnoyarsk | B2: S | C2: клиентское | D2: Илья | G2: уже запущено
A3: Krasnoyarsk | B3: L | C3: Готово | D3: Илья | G3: согласовано, но не запущено
A4: Ufa | B4: m_1 | C4: Готово | D4: Аня
A5: Ufa | B5: m_2 | C5: Готово | D5: Аня
A6: Ufa | B6: l_1 | C6: клиентское | D6: Аня | G6: Цели M2 Ростов | S6: Цели M2 Челябинск | AE6: Цели L Красноярск
A7: Ufa | B7: l_2 | C7: Готово | D7: Аня | G7: вручений | H7: бонус | I7: доплата за вручение | J7: водители на ступени | K7: SR | L7: Затраты | M7: sub/gmv | N7: Метрика | O7: lcv_M2 | S7: вручений | T7: бонус | U7: доплата за вручение | V7: водители на ступени | W7: SR | X7: Затраты | Y7: sub/gmv | Z7: Метрика | AA7: lcv_M2 | AE7: вручений | AF7: бонус | AG7: доплата за вручение | AH7: водители на ступени | AI7: SR | AJ7: Затраты | AK7: sub/gmv | AL7: Метрика | AM7: lcv_l_0
A8: Ufa | B8: xl_0 | C8: Готово | D8: Аня | G8: 15 | H8: 3500 | I8: 233.33333 | J8: 3 | K8: 0.09375 | L8: 10500 | N8: AVG Fare. Май | O8: 2730 | S8: 20 | T8: 3000 | U8: 150 | V8: 2 | W8: 0.125 | X8: 6000 | Z8: AVG Fare. Май | AA8: 2256 | AE8: 10 | AF8: 2000 | AG8: 200 | AH8: 4 | AI8: 0.14814815 | AJ8: 8000 | AL8: AVG Fare. Май | AM8: 1544.0027
A9: Rostov-on-Don | B9: m_2 | C9: Готово | D9: Аня | G9: 20 | H9: 5000 | I9: 250 | J9: 3 | K9: 0.09375 | L9: 15000 | S9: 25 | T9: 4000 | U9: 160 | V9: 0 | W9: 0 | X9: 0 | AE9: 15 | AF9: 3000 | AG9: 200 | AH9: 2 | AI9: 0.074074074 | AJ9: 6000 | AL9: 10% от Ср. Чека | AM9: 154.40027
A10: Rostov-on-Don | B10: l_1 | C10: клиентское | D10: Аня | G10: 25 | H10: 6500 | I10: 260 | J10: 3 | K10: 0.09375 | L10: 19500 | N10: GMV. 26.05 | O10: 557000 | S10: 30 | T10: 6000 | U10: 200 | V10: 3 | W10: 0.1875 | X10: 18000 | Z10: GMV. 26.05 | AA10: 270000 | AE10: 20 | AF10: 4000 | AG10: 200 | AH10: 0 | AI10: 0 | AJ10: 0 | AL10: GMV. 26.05 | AM10: 243405.6
A11: Rostov-on-Don | B11: l_2 | C11: готово | D11: Аня | J11: Всего: | K11: 0.28125 | L11: 45000 | M11: 0.080789946 | V11: Всего: | W11: 0.3125 | X11: 24000 | Y11: 0.088888889 | AH11: Всего: | AI11: 0.22222222 | AJ11: 14000 | AK11: 0.057517165
A12: Novosibirsk | B12: van_2 | C12: готово | D12: Ира
A13: Novosibirsk | B13: m_1 | C13: готово | D13: Ира | G13: Цели L2 Ростов | S13: Цели L2 Челябинск
A14: Novosibirsk | B14: m_2 | C14: готово | D14: Ира | G14: вручений | H14: бонус | I14: доплата за вручение | J14: водители на ступени | K14: SR | L14: Затраты | M14: sub/gmv | N14: Метрика | O14: lcv_l2 | S14: вручений | T14: бонус | U14: доплата за вручение | V14: водители на ступени | W14: SR | X14: Затраты | Y14: sub/gmv | Z14: Метрика | AA14: lcv_l2
A15: Novosibirsk | B15: l_1 | C15: готово | D15: Ира | G15: 15 | H15: 4000 | I15: 266.66667 | J15: 5 | K15: 0.17857143 | L15: 20000 | N15: AVG Fare. Май | O15: 2940 | S15: 20 | T15: 3500 | U15: 175 | V15: 0 | W15: 0 | X15: 0 | Z15: AVG Fare. Май | AA15: 3060
A16: Novosibirsk | B16: l_2 | C16: готово | D16: Ира | G16: 20 | H16: 5500 | I16: 275 | J16: 1 | K16: 0.035714286 | L16: 5500 | S16: 25 | T16: 5000 | U16: 200 | V16: 1 | W16: 0.071428571 | X16: 5000
A17: Chelyabinsk | B17: m_1 | C17: клиентское | D17: Аня | G17: 25 | H17: 7000 | I17: 280 | J17: 3 | K17: 0.10714286 | L17: 21000 | N17: GMV. 26.05 | O17: 636500 | S17: 30 | T17: 7000 | U17: 233.33333 | V17: 3 | W17: 0.21428571 | X17: 21000 | Z17: GMV. 26.05 | AA17: 210000
A18: Chelyabinsk | B18: m_2 | C18: Готово | D18: Аня | J18: Всего: | K18: 0.32142857 | L18: 46500 | M18: 0.073055774 | V18: Всего: | W18: 0.28571429 | X18: 26000 | Y18: 0.12380952
A19: Chelyabinsk | B19: l_1 | C19: клиентское | D19: Аня
A20: Chelyabinsk | B20: l_2 | C20: Готово | D20: Аня
A21: Volgograd | B21: S | C21: Готово | D21: Аня
A22: Volgograd | B22: M2 | C22: Готово | D22: Аня
A23: Volgograd | B23: L | C23: Готово | D23: Аня
A24: Krasnodar | B24: van_2 | C24: Готово | D24: Вова | G24: Цели Van2 Краснодар | S24: Цели Van2 Казань | AE24: Цели Van Волгоград
A25: Krasnodar | B25: m_2 | C25: Клиентские | D25: Вова | G25: вручений | H25: бонус | I25: доплата за вручение | J25: водители на ступени | K25: SR | L25: Затраты | M25: sub/gmv | N25: Метрика | S25: вручений | T25: бонус | U25: доплата за вручение | V25: водители на ступени | W25: SR | X25: Затраты | Y25: sub/gmv | Z25: Метрика | AB25: 10%: | AE25: вручений | AF25: бонус | AG25: доплата за вручение | AH25: водители на ступени | AI25: SR | AJ25: Затраты | AK25: sub/gmv | AL25: Метрика
A26: Krasnodar | B26: L2 | C26: Готово | D26: Вова | G26: 12 | H26: 1500 | I26: 125 | J26: 5 | K26: 0.119 | L26: 7 500 | M26: 0.034 | N26: AVG Fare. Май | O26: 2 300 | S26: 10 | T26: 1700 | U26: 170 | V26: 4 | W26: 0.2222 | X26: 6 800 | Y26: 0.068 | Z26: AVG Fare. Май | AA26: 2 400 | AB26: 240 | AE26: 10 | AF26: 1700 | AG26: 170 | AH26: 4 | AI26: 0.2222 | AJ26: 6 800 | AK26: 0.068 | AL26: AVG Fare. Май | AM26: 2 400
A27: Krasnodar | B27: xl | C27: Готово | D27: Вова | G27: 17 | H27: 2500 | I27: 147 | J27: 3 | K27: 0.0714 | L27: 7 500 | M27: 0.034 | S27: 15 | T27: 3000 | U27: 200 | V27: 1 | W27: 0.0556 | X27: 3 000 | Y27: 0.03 | AE27: 15 | AF27: 3000 | AG27: 200 | AH27: 1 | AI27: 0.0556 | AJ27: 3 000 | AK27: 0.03
A28: Kazan | B28: van_2 | C28: Готово | D28: Вова | G28: 22 | H28: 4000 | I28: 182 | J28: 1 | K28: 0.0238 | L28: 4 000 | M28: 0.018 | N28: GMV. 26.05 | O28: 220 000 | S28: 20 | T28: 4500 | U28: 225 | V28: 0 | W28: 0 | X28: - | Y28: 0 | Z28: GMV. 26.05 | AA28: 100 000 | AE28: 20 | AF28: 4500 | AG28: 225 | AH28: 0 | AI28: 0 | AJ28: - | AK28: 0 | AL28: GMV. 26.05 | AM28: 100 000
A29: Kazan | B29: m_2 | C29: Готово | D29: Вова | J29: Всего: | K29: 0.2143 | L29: 19 000 | M29: 0.086 | V29: Всего: | W29: 0.2778 | X29: 9 800 | Y29: 0.098 | AH29: Всего: | AI29: 0.2778 | AJ29: 9 800 | AK29: 0.093366093
A30: Kazan | B30: l_2 | D30: Вова
A31: Kazan | B31: xl_1 | D31: Вова | G31: Цели L2 Краснодар | S31: Цели M2 Казань | AE31: Цели M2 Волгоград
A32: Perm | B32: M | C32: готово | D32: Ира | G32: вручений | H32: бонус | I32: доплата за вручение | J32: водители на ступени | K32: SR | L32: Затраты | M32: sub/gmv | N32: Метрика | S32: вручений | T32: бонус | U32: доплата за вручение | V32: водители на ступени | W32: SR | X32: Затраты | Y32: sub/gmv | Z32: Метрика | AE32: вручений | AF32: бонус | AG32: доплата за вручение | AH32: водители на ступени | AI32: SR | AJ32: Затраты | AK32: sub/gmv | AL32: Метрика | AM32: lcv_M2
A33: Perm | B33: L | C33: готово | D33: Ира | G33: 5 | H33: 1000 | I33: 200 | J33: 30 | K33: 0.1899 | L33: 30 000 | M33: 0.03 | N33: AVG Fare. Май | O33: 3 500 | S33: 10 | T33: 2000 | U33: 200 | V33: 7 | W33: 0.0909 | X33: 14 000 | Y33: 0.028 | Z33: AVG Fare. Май | AA33: 2 700 | AE33: 16 | AF33: 3000 | AG33: 187.5 | AH33: 2 | AI33: 0.28571429 | AJ33: 6000 | AL33: AVG Fare. Май | AM33: 2980
A34: Saratov | B34: S | C34: в работе | D34: Ира | G34: 10 | H34: 2500 | I34: 250 | J34: 9 | K34: 0.057 | L34: 22 500 | M34: 0.023 | S34: 15 | T34: 3500 | U34: 233 | V34: 3 | W34: 0.039 | X34: 10 500 | Y34: 0.021 | AE34: 20 | AF34: 4000 | AG34: 200 | AH34: 1 | AI34: 0.14285714 | AJ34: 4000
A35: Saratov | B35: m_1 | C35: в работе | D35: Ира | G35: 15 | H35: 4500 | I35: 300 | J35: 3 | K35: 0.019 | L35: 13 500 | M35: 0.014 | N35: GMV. 26.05 | O35: 1 000 000 | S35: 20 | T35: 5500 | U35: 275 | V35: 2 | W35: 0.026 | X35: 11 000 | Y35: 0.022 | Z35: GMV. 26.05 | AA35: 500 000 | AE35: 24 | AF35: 5500 | AG35: 229.16667 | AH35: 0 | AI35: 0 | AJ35: 0 | AL35: GMV. 26.05 | AM35: 143110
A36: Saratov | B36: m_2 | C36: готово | D36: Аня | J36: Всего: | K36: 0.2658 | L36: 66 000 | M36: 0.066 | V36: Всего: | W36: 0.1558 | X36: 35 500 | Y36: 0.071 | AH36: Всего: | AI36: 0.42857143 | AJ36: 10000 | AK36: 0.024570025
A37: Saratov | B37: L | C37: готово | D37: Аня
A38: Voronezh | B38: van_2 | C38: готово | D38: Ира | G38: Цели XL Краснодар | AE38: Цели L Волгоград
A39: Voronezh | B39: M | C39: готово | D39: Ира | G39: вручений | H39: бонус | I39: доплата за вручение | J39: водители на ступени | K39: SR | L39: Затраты | M39: sub/gmv | N39: Метрика | AE39: вручений | AF39: бонус | AG39: доплата за вручение | AH39: водители на ступени | AI39: SR | AJ39: Затраты | AK39: sub/gmv | AL39: Метрика | AM39: lcv_l
A40: Voronezh | B40: L | C40: готово | D40: Ира | G40: 5 | H40: 900 | I40: 180 | J40: 107 | K40: 0.1907 | L40: 96 300 | M40: 0.064 | N40: AVG Fare. Май | O40: 2 500 | AE40: 12 | AF40: 1700 | AG40: 141.66667 | AH40: 5 | AI40: 0.090909091 | AJ40: 8500 | AL40: AVG Fare. Май | AM40: 1320
...

Sheet затраты 21.07
C2: https://datalens.yandex-team.ru/wbenuos6lxv4o-subsidy-details-advanced?tab=8Z&state=9c372b401134 | D2: неделя с 21.07
B3: Zone | C3: на русском | D3: sub/GMV | E3: dXgY | F3: MFG | G3: MFGgeo | H3: Substotal
B4: spb | C4: =VLOOKUP(B4,'население 2023'!C:D,2,0) -> СПб | D4: 0.013 | E4: 756818 | F4: 8098 | G4: 0 | H4: 764916
B5: ekb | C5: =VLOOKUP(B5,'население 2023'!C:D,2,0) -> Екб | D5: 0.05 | E5: 698190 | F5: 18906 | G5: 0 | H5: 717096
B6: nizhnynovgorod | C6: =VLOOKUP(B6,'население 2023'!C:D,2,0) -> НиНо | D6: 0.092 | E6: 475066 | F6: 32126 | G6: 0 | H6: 507191
B7: novosibirsk | C7: =VLOOKUP(B7,'население 2023'!C:D,2,0) -> Нск | D7: 0.027 | E7: 321639 | F7: 91550 | G7: 0 | H7: 415189
B8: krasnodar | C8: =VLOOKUP(B8,'население 2023'!C:D,2,0) -> Краснодар | D8: 0.015 | E8: 253000 | F8: 39950 | G8: 0 | H8: 294699
B9: perm | C9: =VLOOKUP(B9,'население 2023'!C:D,2,0) -> Пермь | D9: 0.082 | E9: 246709 | F9: 43963 | G9: 0 | H9: 290672
B10: samara | C10: =VLOOKUP(B10,'население 2023'!C:D,2,0) -> Самара | D10: 0.056 | E10: 198851 | F10: 43859 | G10: 0 | H10: 242711
B11: kazan | C11: =VLOOKUP(B11,'население 2023'!C:D,2,0) -> Казань | D11: 0.027 | E11: 203000 | F11: 29646 | G11: 0 | H11: 232646
B12: rostovondon | C12: =VLOOKUP(B12,'население 2023'!C:D,2,0) -> РнД | D12: 0.02 | E12: 177603 | F12: 17948 | G12: 0 | H12: 195551
B13: volgograd | C13: =VLOOKUP(B13,'население 2023'!C:D,2,0) -> Влг | D13: 0.071 | E13: 129219 | F13: 9543 | G13: 0 | H13: 138763
B14: sochi | C14: =VLOOKUP(B14,'население 2023'!C:D,2,0) -> Сочи | D14: 0.089 | E14: 78595 | F14: 32947 | G14: 0 | H14: 111542
B15: omsk | C15: =VLOOKUP(B15,'население 2023'!C:D,2,0) -> Омск | D15: 0.053 | E15: 103592 | F15: 3614 | G15: 0 | H15: 107206
... B42: penza | C42: =VLOOKUP(B42,'население 2023'!C:D,2,0) -> Пенза | D42: 0.017 | E42: 0 | F42: 11382 | G42: 0 | H42: 11382
B43: krasnoe_selo | C43: Красное село | D43: 0.008 | E43: 10983 | F43: 170 | G43: 0 | H43: 11153
B44: akademgorod | C44: =VLOOKUP(B44,'население 2023'!C:D,2,0) -> #N/A | D44: 0.014 | E44: 4230 | F44: 3106 | G44: 0 | H44: 10336
B45: odincovo | C45: =VLOOKUP(B45,'население 2023'!C:D,2,0) -> Одинцово | D45: 0.001 | E45: 5446 | F45: 1855 | G45: 0 | H45: 7302
B46: tomsk | C46: =VLOOKUP(B46,'население 2023'!C:D,2,0) -> Томск | D46: 0.061 | E46: 7100 | F46: 116 | G46: 0 | H46: 7216
B47: podolsk | C47: =VLOOKUP(B47,'население 2023'!C:D,2,0) -> Подольск | D47: 0.001 | E47: 0 | F47: 5514 | G47: 1437 | H47: 6951
B48: pushkin | C48: =VLOOKUP(B48,'население 2023'!C:D,2,0) -> #N/A | D48: 0.005 | E48: 6803 | F48: 26 | G48: 0 | H48: 6830
B49: yaroslavl | C49: =VLOOKUP(B49,'население 2023'!C:D,2,0) -> Ярославль | D49: 0.11 | E49: 6200 | F49: 530 | G49: 0 | H49: 6730
B50: lipetsk | C50: =VLOOKUP(B50,'население 2023'!C:D,2,0) -> Липецк | D50: 0.164 | E50: 5300 | F50: 852 | G50: 0 | H50: 6152
B51: makhachkala | C51: =VLOOKUP(B51,'население 2023'!C:D,2,0) -> Макхачкала | D51: 0.093 | E51: 5246 | F51: 660 | G51: 0 | H51: 5906
B52: ryazan | C52: =VLOOKUP(B52,'население 2023'!C:D,2,0) -> Рязань | D52: 0.03 | E52: 4295 | F52: 970 | G52: 0 | H52: 5265
B53: kostroma | C53: =VLOOKUP(B53,'население 2023'!C:D,2,0) -> Кострома | D53: 0.232 | E53: 2000 | F53: 3065 | G53: 0 | H53: 5065
B54: tver | C54: =VLOOKUP(B54,'население 2023'!C:D,2,0) -> Тверь | D54: 0.008 | E54: 0 | F54: 4963 | G54: 0 | H54: 4963
B55: taganrog | C55: =VLOOKUP(B55,'население 2023'!C:D,2,0) -> Таганрог | D55: 0.081 | E55: 3955 | F55: 734 | G55: 0 | H55: 4689
... B100: istra | C100: =VLOOKUP(B100,'население 2023'!C:D,2,0) -> Истра | D100: 0 | E100: 0 | F100: 318 | G100: 0 | H100: 318
B101: krasnayapolyana | C101: Красная поляна | D101: 0.01 | E101: 277 | F101: 0 | G101: 0 | H101: 277
B102: monino | C102: =VLOOKUP(B102,'население 2023'!C:D,2,0) -> #N/A | D102: 0 | E102: 0 | F102: 239 | G102: 0 | H102: 239
B103: kaspiysk | C103: =VLOOKUP(B103,'население 2023'!C:D,2,0) -> Каспийск | D103: 0.014 | E103: 156 | F103: 0 | G103: 0 | H103: 156

Sheet доставки за июнь
B2: Агломерация | C2: Популяция | D2: доставки за июнь | E2: тарифная зона
B3: Moscow | C3: Москва | D3: 441709 | E3: moscow
B4: Saint-Petersburg | C4: СПб | D4: 126609 | E4: spb
B5: Krasnodar | C5: 1 млн+ | D5: 63368 | E5: krasnodar
B6: Novosibirsk | C6: 1 млн+ | D6: 50424 | E6: novosibirsk
B7: Ekaterinburg | C7: 1 млн+ | D7: 40797 | E7: ekb
B8: Rostov-on-Don | C8: 1 млн+ | D8: 33209 | E8: rostovondon
B9: Kazan | C9: 1 млн+ | D9: 26018 | E9: kazan
B10: Chelyabinsk | C10: 1 млн+ | D10: 23161 | E10: chelyabinsk
B11: Nizhny Novgorod | C11: 1 млн+ | D11: 22951 | E11: nizhnynovgorod
B12: Samara | C12: 1 млн+ | D12: 15860 | E12: samara
B13: Perm | C13: 1 млн+ | D13: 11226 | E13: perm
B14: Ufa | C14: 1 млн+ | D14: 11060 | E14: ufa
... B114: Shatura | C114: 100- (ДМО) | D114: 1 | E114: shatura

Sheet Цели Красноярск S
A1: Доходимость S за 02.07 | D1: Доходимость S за 25.06 | K1: Cancels indicators - Cancels: Corporate Clients & C2C - Yandex DataLens
A2: Итого | B2: COUNTA из executor_profile_id | D2: Итого | E2: COUNTA из executor_profile_id
A3: 1 | B3: 4 | C3: =A3*B3 -> 4 | D3: 1 | E3: 4 | F3: =D3*E3 -> 4
A4: 2 | B4: 2 | C4: =A4*B4 -> 4 | D4: 3 | E4: 1 | F4: =D4*E4 -> 3
A5: 3 | B5: 3 | C5: =A5*B5 -> 9 | D5: 5 | E5: 1 | F5: =D5*E5 -> 5
A6: 4 | B6: 1 | C6: =A6*B6 -> 4 | D6: 6 | E6: 2 | F6: =D6*E6 -> 12
A7: 5 | B7: 1 | C7: =A7*B7 -> 5 | D7: 7 | E7: 2 | F7: =D7*E7 -> 14
A8: 6 | B8: 2 | C8: =A8*B8 -> 12 | D8: 8 | E8: 2 | F8: =D8*E8 -> 16
A9: 7 | B9: 4 | C9: =A9*B9 -> 28 | D9: 9 | E9: 2 | F9: =D9*E9 -> 18
A10: 8 | B10: 4 | C10: =A10*B10 -> 32 | D10: 10 | E10: 3 | F10: =D10*E10 -> 30
A11: 11 | B11: 3 | C11: =A11*B11 -> 33 | D11: 12 | E11: 1 | F11: =D11*E11 -> 12
A12: 14 | B12: 1 | C12: =A12*B12 -> 14 | D12: 14 | E12: 1 | F12: =D12*E12 -> 14
A13: 16 | B13: 1 | C13: =A13*B13 -> 16 | D13: 15 | E13: 1 | F13: =D13*E13 -> 15
A14: 17 | B14: 2 | C14: =A14*B14 -> 34 | D14: 16 | E14: 3 | F14: =D14*E14 -> 48
... A16: 21 | B16: 2 | C16: =A16*B16 -> 42 | D16: 21 | E16: 1 | F16: =D16*E16 -> 21
A17: Итого | B17: 33 | C17: =SUM(C3:C16) -> 294 | D17: 24 | E17: 1 | F17: =D17*E17 -> 24
D18: 31 | E18: 1 | F18: =D18*E18 -> 31
D19: Итого | E19: 27 | F19: =SUM(F3:F18) -> 285
A23: 45840 | K23: 45833
A24: Цели S вариант 1 | H24: Метрика | I24: lcv_s | K24: вручений | L24: бонус | M24: доплата за вручение | N24: водители на ступени | O24: SR
A25: вручений | B25: бонус | C25: доплата за вручение | D25: водители на ступени | E25: SR | F25: Затраты | G25: sub/gmv | H25: AVG Fare. Июнь | I25: 1021 | K25: 15 | L25: 1400 | M25: =L25/K25 -> 93.333333 | N25: 5 | O25: =N25/27 -> 0.18518519
A26: 15 | B26: 1400 | C26: =B26/A26 -> 93.333333 | D26: 6 | E26: =D26/$B$17 -> 0.18181818 | F26: =B26*D26 -> 8400 | H26: 10% от Ср. Чека | I26: 102 | K26: 20 | L26: 2200 | M26: =L26/K26 -> 110 | N26: 2 | O26: =N26/27 -> 0.074074074
A27: 20 | B27: 2200 | C27: =B27/A27 -> 110 | D27: 2 | E27: =D27/$B$17 -> 0.060606061 | F27: =B27*D27 -> 4400 | H27: GMV. 02/07 | I27: 476692 | K27: 25 | L27: 3000 | M27: =L27/K27 -> 120 | N27: 1 | O27: =N27/27 -> 0.037037037
A28: 25 | B28: 3000 | C28: =B28/A28 -> 120 | D28: 0 | E28: =D28/$B$17 -> 0 | F28: =B28*D28 -> 0 | I28: 1686003 | N28: Всего: | O28: =SUM(O25:O27) -> 0.2962963
D29: Всего: | E29: =SUM(E26:E28) -> 0.24242424 | F29: =SUM(F26:F28) -> 12800 | G29: =F29/I27 -> 0.02685172 | H29: =F29/I28 -> 0.0075919201
K30: Цели S вариант 2
A31: Цели S вариант 2 | H31: Метрика | I31: lcv_s | K31: вручений | L31: бонус | M31: доплата за вручение | N31: водители на ступени | O31: SR
A32: вручений | B32: бонус | C32: доплата за вручение | D32: водители на ступени | E32: SR | F32: Затраты | G32: sub/gmv | H32: AVG Fare. Июнь | I32: 1021 | K32: 14 | L32: 1200 | M32: =L32/K32 -> 85.714286 | N32: 6 | O32: =N32/27 -> 0.22222222
A33: 14 | B33: 1200 | C33: =B33/A33 -> 85.714286 | D33: 6 | E33: =D33/$B$17 -> 0.18181818 | F33: =B33*D33 -> 7200 | H33: 10% от Ср. Чека | I33: 102 | K33: 19 | L33: 1900 | M33: =L33/K33 -> 100 | N33: 1 | O33: =N33/27 -> 0.037037037
A34: 19 | B34: 1900 | C34: =B34/A34 -> 100 | D34: 1 | E34: =D34/$B$17 -> 0.03030303 | F34: =B34*D34 -> 1900 | H34: GMV. 02/07 | I34: 476692 | K34: 24 | L34: 2600 | M34: =L34/K34 -> 108.33333 | N34: 2 | O34: =N34/27 -> 0.074074074
A35: 24 | B35: 2600 | C35: =B35/A35 -> 108.33333 | D35: 2 | E35: =D35/$B$17 -> 0.060606061 | F35: =B35*D35 -> 5200 | I35: 1686003 | N35: Всего: | O35: =SUM(O32:O34) -> 0.33333333
D36: Всего: | E36: =SUM(E33:E35) -> 0.27272727 | F36: =SUM(F33:F35) -> 14300 | G36: =F36/I34 -> 0.029998406 | H36: =F36/I35 -> 0.0084815982
A41: Доходимость S2 за 25.06 | D41: Доходимость S2 за 17.06 | G41: за 02.07 отсутствует
A42: Итого | B42: COUNTA из executor_profile_id | D42: Итого | E42: COUNTA из executor_profile_id
A43: 18 | B43: 1 | D43: 6 | E43: 1
A44: Итого | B44: 1 | D44: Итого | E44: 1
A47: Цели S2 вариант 1 | H47: Метрика | I47: lcv_s
A48: вручений | B48: бонус | C48: доплата за вручение | D48: водители на ступени | E48: SR | F48: Затраты | G48: sub/gmv | H48: AVG Fare. Июнь | I48: 2267
A49: 6 | B49: 1400 | C49: =B49/A49 -> 233.33333 | D49: 0 | E49: =D49/$B$17 -> 0 | F49: =B49*D49 -> 0 | H49: 10% от Ср. Чека | I49: 227
A50: 12 | B50: 2200 | C50: =B50/A50 -> 183.33333 | D50: 0 | E50: =D50/$B$17 -> 0 | F50: =B50*D50 -> 0 | H50: GMV. 17/06 | I50: 6620
...

Sheet выгрузка СПб (кузова)
A1: dt | B1: lcv_l | C1: lcv_m | D1: lcv_xl | E1: truck_5t | F1: van
A2: AVG Fare. Май | B2: 2670.4182 | C2: 2059.9928 | D2: 2964.8335 | E2: 1983.6332 | F2: 1475.6222
A3: GMV. 26.05 | B3: 8485381.2 | C3: 17363074 | D3: 3333006.4 | E3: 584373.8 | F3: 21760074 | G3: https://datalens.yandex-team.ru/sne8u5ggtwoih-cdr-utilization-per-option-region?tab=Aj&state=5c2bf175953

Sheet экипажи на 26.06
A1: Город | B1: Кузов | C1: Опция | D1: Версия Экипажей | E1: Квота в неделю | F1: Бонус
A2: Волгоград | B2: М | C2: M2 | D2: 4.0 | E2: 13 | F2: 1000 руб/заказ
A3: Волгоград | B3: L | C3: L1 | D3: 142 | E3: 3 | F3: 1000руб/час
A4: Екатеринбург | B4: L | C4: L2 | D4: 4.0 | E4: 28 | F4: 1000 руб/заказ
A5: Казань | B5: L | C5: L2 | D5: 4.0 | E5: 31 | F5: 1000 руб/заказ
A6: Казань | B6: М | C6: M2 | D6: 4.0 | E6: 30 | F6: 1000 руб/заказ
A7: Казань | B7: XXL | C7: XXL0 | D7: 3.0 | E7: 21 | F7: 1400 руб/час
A8: Красноярск | B8: L | C8: L1 | D8: 3.0 | E8: 21 | F8: 1400 руб/час
A9: Красноярск | B9: S | C9: S1 | D9: 142 | E9: 35 | F9: 800 руб/час
A10: Нижний Новогород | B10: М | C10: M2 | D10: 4.0 | E10: 18 | F10: 1000 руб/заказ
A11: Нижний Новогород | B11: L | C11: L2 | D11: 4.0 | E11: 41 | F11: 1000 руб/заказ
A12: Нижний Новогород | B12: XXL | C12: XXL0 | D12: 3.0 | E12: 14 | F12: 1400 руб/час
A13: Нижний Тагил | B13: М | C13: M1 | D13: 142 | E13: 14 | F13: 700 руб/час
A14: Новосибирск | B14: L | C14: L2 | D14: 4.0 | E14: 35 | F14: 1000 руб/заказ
A15: Омск | B15: L | C15: L2 | D15: 3.0 | E15: 35 | F15: 1200 руб/час
A16: Пермь | B16: М | C16: M2 | D16: 4.0 | E16: 6 | F16: 1000 руб/заказ
A17: Сочи | B17: L | C17: L2 | D17: 3.0 | E17: 28 | F17: 1000 руб/заказ
A18: Сыктывкар | B18: S | C18: S1 | D18: 142 | E18: 7 | F18: 500 руб/час
A19: Сыктывкар | B19: M | C19: M1 | D19: 142 | E19: 7 | F19: 600 руб/час
A20: Тюмень | B20: L | C20: L2 | D20: 4.0 | E20: 35 | F20: 1000 руб/заказ
A21: Уфа | B21: L | C21: L2 | D21: 3.0 | E21: 35 | F21: 1200 руб/час
A22: Челябинск | B22: L | C22: L2 | D22: 4.0 | E22: 28 | F22: 1000 руб/заказ
A23: Шахты | B23: М | C23: M1 | D23: 142 | E23: 7 | F23: 600 руб/час

Sheet слоты

Sheet СПб XL2
A1: дох-сть 09.06 XL2 | D1: as is дневные цели | Q1: 02.06 доходимость XL2
A2: COUNTA из order_id | B2: COUNTA из executor_profile_id | D2: вручений | E2: бонус | F2: доплата за вручение | G2: водители на ступени | H2: SR | I2: Затраты | Q2: COUNTA из order_id | R2: COUNTA из executor_profile_id
A3: 1 | B3: 1 | D3: 2 | E3: 1200 | F3: =E3/D3 -> 600 | G3: 4 | H3: =G3/20 -> 0.2 | I3: =E3*G3 -> 4800 | Q3: 1 | R3: 3
A4: 2 | B4: 4 | D4: 3 | E4: 2300 | F4: =E4/D4 -> 766.66667 | G4: 15 | H4: =G4/20 -> 0.75 | I4: =E4*G4 -> 34500 | Q4: 2 | R4: 3
A5: 3 | B5: 7 | G5: Всего: | H5: =SUM(H2:H4) -> 0.95 | I5: =SUM(I2:I4) -> 39300 | Q5: 3 | R5: 5
A6: 4 | B6: 3 | Q6: 4 | R6: 9
A7: 5 | B7: 4 | D7: to be | Q7: 5 | R7: 7
A8: 6 | B8: 1 | D8: вручений | E8: бонус | F8: доплата за вручение | G8: водители на ступени | H8: SR | I8: Затраты | Q8: 6 | R8: 4
A9: Итого | B9: 20 | D9: 2 | E9: 1200 | F9: =E9/D9 -> 600 | G9: 4 | H9: =G9/20 -> 0.2 | I9: =E9*G9 -> 4800 | Q9: 7 | R9: 5
D10: 3 | E10: 2500 | F10: =E10/D10 -> 833.33333 | G10: 7 | H10: =G10/20 -> 0.35 | I10: =E10*G10 -> 17500 | Q10: 8 | R10: 2
D11: 4 | E11: 4000 | F11: =E11/D11 -> 1000 | G11: 8 | H11: =G11/20 -> 0.4 | I11: =E11*G11 -> 32000 | Q11: 9 | R11: 1
G12: Всего: | H12: =SUM(H9:H11) -> 0.95 | I12: =SUM(I9:I11) -> 54300 | Q12: 10 | R12: 2
Q13: 11 | R13: 2
Q14: 12 | R14: 4
Q15: 13 | R15: 3
Q16: 14 | R16: 1
Q17: 15 | R17: 4
Q18: 17 | R18: 3
Q19: 18 | R19: 1
Q20: 19 | R20: 2
Q21: 20 | R21: 2
Q22: 22 | R22: 1
Q23: Итого | R23: 64

Sheet СПб
A1: Цели XL | C1: Доходимость за 02.06 XL | Q1: Цели L | AG1: Цели M | AI1: Доходимость за 02.06 M | AW1: Цели S | AY1: Доходимость S
C2: COUNTA из order_id | D2: COUNTA из executor_profile_id | F2: 1 вариант целей XL | S2: Доходимость за 02.06 L | V2: 1 вариант целей L | AI2: Кол-во вручений | AJ2: Водителей | AL2: 1 вариант целей M | AY2: Кол-во вручений | AZ2: Водителей | BB2: 1 вариант целей S
C3: 1 | D3: 24 | F3: вручений | G3: бонус | H3: доплата за вручение | I3: водители на ступени | J3: SR | K3: Затраты | L3: sub/gmv | N3: Метрика | O3: lcv_xl | S3: Кол-во вручений | T3: Водителей | V3: вручений | W3: бонус | X3: доплата за вручение | Y3: водители на ступени | Z3: SR | AA3: Затраты | AB3: sub/gmv | AD3: Метрика | AE3: lcv_l | AI3: 1 | AJ3: 94 | AL3: вручений | AM3: бонус | AN3: доплата за вручение | AO3: водители на ступени | AP3: SR | AQ3: Затраты | AR3: sub/gmv | AT3: Метрика | AU3: lcv_m | AY3: 1 | AZ3: 126 | BB3: вручений | BC3: бонус | BD3: доплата за вручение | BE3: водители на ступени | BF3: SR | BG3: Затраты | BH3: sub/gmv | BJ3: Метрика | BK3: van
C4: 2 | D4: 26 | F4: 10 | G4: 2500 | H4: =G4/F4 -> 250 | I4: 38 | J4: =I4/$D$25 -> 0.17117117 | K4: =G4*I4 -> 95000 | N4: AVG Fare. Май | O4: =HLOOKUP(O3,'выгрузка СПб (кузова)'!$B$1:$J$3,2,0) -> 2964.8335 | S4: 1 | T4: 54 | V4: 12 | W4: 2400 | X4: =W4/V4 -> 200 | Y4: 49 | Z4: =Y4/394 -> 0.12436548 | AA4: =W4*Y4 -> 117600 | AD4: AVG Fare. Май | AE4: =HLOOKUP(AE3,'выгрузка СПб (кузова)'!$B$1:$J$3,2,0) -> 2670.4182 | AI4: 2 | AJ4: 69 | AL4: 15 | AM4: 2400 | AN4: =AM4/AL4 -> 160 | AO4: 79 | AP4: =AO4/741 -> 0.10661269 | AQ4: =AM4*AO4 -> 189600 | AT4: AVG Fare. Май | AU4: =HLOOKUP(AU3,'выгрузка СПб (кузова)'!$B$1:$J$3,2,0) -> 2059.9928 | AY4: 2 | AZ4: 89 | BB4: 15 | BC4: 1600 | BD4: =BC4/BB4 -> 106.66667 | BE4: 111 | BF4: =BE4/1041 -> 0.10662824 | BG4: =BC4*BE4 -> 177600 | BJ4: AVG Fare. Май | BK4: =HLOOKUP(BK3,'выгрузка СПб (кузова)'!$B$1:$J$3,2,0) -> 1475.6222
C5: 3 | D5: 27 | F5: 15 | G5: 4000 | H5: =G5/F5 -> 266.66667 | I5: 17 | J5: =I5/$D$25 -> 0.076576577 | K5: =G5*I5 -> 68000 | N5: 10% от Ср. Чека | O5: =O4/10 -> 296.48335 | S5: 2 | T5: 43 | V5: 17 | W5: 3600 | X5: =W5/V5 -> 211.76471 | Y5: 24 | Z5: =Y5/394 -> 0.060913706 | AA5: =W5*Y5 -> 86400 | AD5: 10% от Ср. Чека | AE5: =AE4/10 -> 267.04182 | AI5: 3 | AJ5: 64 | AL5: 20 | AM5: 3600 | AN5: =AM5/AL5 -> 180 | AO5: 55 | AP5: =AO5/741 -> 0.074224022 | AQ5: =AM5*AO5 -> 198000 | AT5: 10% от Ср. Чека | AU5: =AU4/10 -> 205.99928 | AY5: 3 | AZ5: 68 | BB5: 20 | BC5: 2500 | BD5: =BC5/BB5 -> 125 | BE5: 73 | BF5: =BE5/1041 -> 0.07012488 | BG5: =BC5*BE5 -> 182500 | BJ5: 10% от Ср. Чека | BK5: =BK4/10 -> 147.56222
C6: 4 | D6: 18 | F6: 20 | G6: 5800 | H6: =G6/F6 -> 290 | I6: 8 | J6: =I6/$D$25 -> 0.036036036 | K6: =G6*I6 -> 46400 | N6: GMV. 26.05 | O6: =HLOOKUP(O3,'выгрузка СПб (кузова)'!$B$1:$J$3,3,0) -> 3333006.4 | S6: 3 | T6: 42 | V6: 22 | W6: 5200 | X6: =W6/V6 -> 236.36364 | Y6: 15 | Z6: =Y6/394 -> 0.038071066 | AA6: =W6*Y6 -> 78000 | AD6: GMV. 26.05 | AE6: =HLOOKUP(AE3,'выгрузка СПб (кузова)'!$B$1:$J$3,3,0) -> 8485381.2 | AI6: 4 | AJ6: 56 | AL6: 25 | AM6: 5000 | AN6: =AM6/AL6 -> 200 | AO6: 41 | AP6: =AO6/741 -> 0.055330634 | AQ6: =AM6*AO6 -> 205000 | AT6: GMV. 26.05 | AU6: =HLOOKUP(AU3,'выгрузка СПб (кузова)'!$B$1:$J$3,3,0) -> 17363074 | AY6: 4 | AZ6: 59 | BB6: 25 | BC6: 3800 | BD6: =BC6/BB6 -> 152 | BE6: 130 | BF6: =BE6/1041 -> 0.12487992 | BG6: =BC6*BE6 -> 494000 | BJ6: GMV. 26.05 | BK6: =HLOOKUP(BK3,'выгрузка СПб (кузова)'!$B$1:$J$3,3,0) -> 21760074
C7: 5 | D7: 20 | I7: Всего: | J7: =SUM(J4:J6) -> 0.28378378 | K7: =SUM(K4:K6) -> 209400 | L7: =K7/$AE$6 -> 0.024677736 | S7: 4 | T7: 29 | Y7: Всего: | Z7: =SUM(Z4:Z6) -> 0.22335025 | AA7: =SUM(AA4:AA6) -> 282000 | AB7: =AA7/$AE$6 -> 0.033233628 | AI7: 5 | AJ7: 50 | AO7: Всего: | AP7: =SUM(AP4:AP6) -> 0.23616734 | AQ7: =SUM(AQ4:AQ6) -> 592600 | AR7: =AQ7/$AU$6 -> 0.034129901 | AY7: 5 | AZ7: 64 | BE7: Всего: | BF7: =SUM(BF4:BF6) -> 0.30163305 | BG7: =SUM(BG4:BG6) -> 854100 | BH7: =BG7/$BK$6 -> 0.039250786
C8: 6 | D8: 14 | S8: 5 | T8: 24 | AI8: 6 | AJ8: 37 | AY8: 6 | AZ8: 56
C9: 7 | D9: 14 | F9: 2 вариант целей XL | S9: 6 | T9: 22 | V9: 2 вариант целей L | AI9: 7 | AJ9: 27 | AY9: 7 | AZ9: 39 | BB9: 2 вариант целей S
C10: 8 | D10: 8 | F10: вручений | G10: бонус | H10: доплата за вручение | I10: водители на ступени | J10: SR | K10: Затраты | L10: sub/gmv | S10: 7 | T10: 19 | V10: вручений | W10: бонус | X10: доплата за вручение | Y10: водители на ступени | Z10: SR | AA10: Затраты | AB10: sub/gmv | AI10: 8 | AJ10: 23 | AL10: 2 вариант целей M | AY10: 8 | AZ10: 36 | BB10: вручений | BC10: бонус | BD10: доплата за вручение | BE10: водители на ступени | BF10: SR | BG10: Затраты | BH10: sub/gmv
C11: 9 | D11: 8 | F11: 12 | G11: 3000 | H11: =G11/F11 -> 250 | I11: 32 | J11: =I11/$D$25 -> 0.14414414 | K11: =G11*I11 -> 96000 | S11: 8 | T11: 23 | V11: 15 | W11: 3000 | X11: =W11/V11 -> 200 | Y11: 30 | Z11: =Y11/394 -> 0.076142132 | AA11: =W11*Y11 -> 90000 | AI11: 9 | AJ11: 29 | AL11: вручений | AM11: бонус | AN11: доплата за вручение | AO11: водители на ступени | AP11: SR | AQ11: Затраты | AR11: sub/gmv | AY11: 9 | AZ11: 31 | BB11: 20 | BC11: 2200 | BD11: =BC11/BB11 -> 110 | BE11: 73 | BF11: =BE11/1041 -> 0.07012488 | BG11: =BC11*BE11 -> 160600
C12: 10 | D12: 7 | F12: 17 | G12: 4500 | H12: =G12/F12 -> 264.70588 | I12: 13 | J12: =I12/$D$25 -> 0.058558559 | K12: =G12*I12 -> 58500 | S12: 9 | T12: 15 | V12: 20 | W12: 4400 | X12: =W12/V12 -> 220 | Y12: 24 | Z12: =Y12/394 -> 0.060913706 | AA12: =W12*Y12 -> 105600 | AI12: 10 | AJ12: 33 | AL12: 20 | AM12: 3200 | AN12: =AM12/AL12 -> 160 | AO12: 55 | AP12: =AO12/741 -> 0.074224022 | AQ12: =AM12*AO12 -> 176000 | AY12: 10 | AZ12: 35 | BB12: 25 | BC12: 3200 | BD12: =BC12/BB12 -> 128 | BE12: 51 | BF12: =BE12/1041 -> 0.048991354 | BG12: =BC12*BE12 -> 163200
C13: 11 | D13: 6 | F13: 22 | G13: 6400 | H13: =G13/F13 -> 290.90909 | I13: 5 | J13: =I13/$D$25 -> 0.022522523 | K13: =G13*I13 -> 32000 | S13: 10 | T13: 21 | V13: 25 | W13: 6000 | X13: =W13/V13 -> 240 | Y13: 5 | Z13: =Y13/394 -> 0.012690355 | AA13: =W13*Y13 -> 30000 | AI13: 11 | AJ13: 28 | AL13: 25 | AM13: 4400 | AN13: =AM13/AL13 -> 176 | AO13: 22 | AP13: =AO13/741 -> 0.029689609 | AQ13: =AM13*AO13 -> 96800 | AY13: 11 | AZ13: 40 | BB13: 30 | BC13: 4600 | BD13: =BC13/BB13 -> 153.33333 | BE13: 79 | BF13: =BE13/1041 -> 0.075888569 | BG13: =BC13*BE13 -> 363400
